Workbook

Sheet Output＞＞

Sheet PL
A1: 単位：千円、％
D3: 24年 | E3: 25年 | F3: 26年 | G3: 27年 | H3: 28年 | I3: 29年 | J3: 30年 | K3: 31年 | L3: 32年 | M3: 33年 | N3: 34年
A4: 全体 | B4: 売上高計 | D4: =D38 -> 213867.54 | E4: =E38 -> 398510.32 | F4: =F38 -> 887604.91 | G4: =G38 -> 1570742.7 | H4: =H38 -> 2355042.8 | I4: =I38 -> 3085274.9 | J4: =J38 -> 3765793.8 | K4: =K38 -> 4400581.2 | ... N4: =N38 -> 6065468.6
B5: 粗利 | D5: =D56 -> 141818.44 | E5: =E56 -> 315192.44 | F5: =F56 -> 783612.99 | G5: =G56 -> 1437511.8 | H5: =H56 -> 2190457.9 | I5: =I56 -> 2893098.4 | J5: =J56 -> 3549336.8 | K5: =K56 -> 4162757.3 | ... N5: =N56 -> 5777734.4
B6: 限界利益 | D6: =D74 -> 78150.005 | E6: =E74 -> 169988.04 | F6: =F74 -> 416077.98 | G6: =G74 -> 759305.2 | H6: =H74 -> 1152130.7 | I6: =I74 -> 1515355.1 | J6: =J74 -> 1851398.7 | K6: =K74 -> 2162470.5 | ... N6: =N74 -> 2965180.4
C7: 限界利益率 | D7: =D119 -> 0.36541311 | E7: =E119 -> 0.42655871 | F7: =F119 -> 0.46876485 | G7: =G119 -> 0.48340522 | H7: =H119 -> 0.48921859 | I7: =I119 -> 0.49115724 | J7: =J119 -> 0.4916357 | K7: =K119 -> 0.49140566 | ... N7: =N119 -> 0.48886254
B8: 直接利益 | D8: =D92 -> 48526.676 | E8: =E92 -> 23355.44 | F8: =F92 -> 214425.3 | G8: =G92 -> 525508.25 | H8: =H92 -> 889759.94 | I8: =I92 -> 1225293.9 | J8: =J92 -> 1534468.7 | K8: =K92 -> 1819435.9 | ... N8: =N92 -> 2547899.8
C9: 直接利益率 | D9: =D128 -> 0.22690061 | E9: =E128 -> 0.058606863 | F9: =F128 -> 0.24157742 | G9: =G128 -> 0.33456038 | H9: =H128 -> 0.37781052 | I9: =I128 -> 0.39714255 | J9: =J128 -> 0.4074755 | K9: =K128 -> 0.41345354 | ... N9: =N128 -> 0.42006645
B10: 営業利益 | D10: =D110 -> 48315.807 | E10: =E110 -> -2618.1223 | F10: =F110 -> 148572.95 | G10: =G110 -> 441478.86 | H10: =H110 -> 786748.93 | I10: =I110 -> 1104979.1 | J10: =J110 -> 1398326.5 | K10: =K110 -> 1668765.6 | ... N10: =N110 -> 2359973.2
C11: 営業利益率 | D11: =D137 -> 0.22591463 | E11: =E137 -> -0.006569773 | F11: =F137 -> 0.16738636 | G11: =G137 -> 0.28106378 | H11: =H137 -> 0.33406991 | I11: =I137 -> 0.35814608 | J11: =J137 -> 0.37132318 | K11: =K137 -> 0.37921482 | ... N11: =N137 -> 0.3890834
D13: 24年 | E13: 25年 | F13: 26年 | G13: 27年 | H13: 28年 | I13: 29年 | J13: 30年 | K13: 31年 | L13: 32年 | M13: 33年 | N13: 34年
A14: アプリ | B14: 売上高計 | D14: =D39 -> 31621.632 | E14: =E39 -> 160180.98 | F14: =F39 -> 538435.04 | G14: =G39 -> 1064836.5 | H14: =H39 -> 1674358.4 | I14: =I39 -> 2241213.9 | J14: =J39 -> 2768389.5 | K14: =K39 -> 3258662.7 | ... N14: =N39 -> 4533009
B15: 粗利 | D15: =D57 -> 31621.632 | E15: =E57 -> 160180.98 | F15: =F57 -> 538435.04 | G15: =G57 -> 1064836.5 | H15: =H57 -> 1674358.4 | I15: =I57 -> 2241213.9 | J15: =J57 -> 2768389.5 | K15: =K57 -> 3258662.7 | ... N15: =N57 -> 4533009
B16: 限界利益 | D16: =D75 -> 16776.923 | E16: =E75 -> 84984.353 | F16: =F75 -> 285667.83 | G16: =G75 -> 564951.2 | H16: =H75 -> 888334.36 | I16: =I75 -> 1189080.7 | J16: =J75 -> 1468774.8 | K16: =K75 -> 1728890.3 | ... N16: =N75 -> 2404997.4
C17: 限界利益率 | D17: =D120 -> 0.53055208 | E17: =E120 -> 0.53055208 | F17: =F120 -> 0.53055208 | G17: =G120 -> 0.53055208 | H17: =H120 -> 0.53055208 | I17: =I120 -> 0.53055208 | J17: =J120 -> 0.53055208 | K17: =K120 -> 0.53055208 | ... N17: =N120 -> 0.53055208
B18: 直接利益 | D18: =D93 -> 9238.9227 | E18: =E93 -> 17230.104 | F18: =F93 -> 176250.16 | G18: =G93 -> 441422.15 | H18: =H93 -> 749375.57 | I18: =I93 -> 1037071 | J18: =J93 -> 1305108.4 | K18: =K93 -> 1554616.3 | ... N18: =N93 -> 2203755.6
C19: 直接利益率 | D19: =D129 -> 0.29217096 | E19: =E129 -> 0.10756648 | F19: =F129 -> 0.32733784 | G19: =G129 -> 0.41454455 | H19: =H129 -> 0.44755982 | I19: =I129 -> 0.46272736 | J19: =J129 -> 0.47143238 | K19: =K129 -> 0.47707186 | ... N19: =N129 -> 0.48615735
B20: 営業利益 | D20: =D111 -> 9238.9227 | E20: =E111 -> 6230.1043 | F20: =F111 -> 135250.16 | G20: =G111 -> 395422.15 | H20: =H111 -> 698375.57 | I20: =I111 -> 981071 | J20: =J111 -> 1244108.4 | K20: =K111 -> 1488616.3 | ... N20: =N111 -> 2122755.6
C21: 営業利益率 | D21: =D138 -> 0.29217096 | E21: =E138 -> 0.038894158 | F21: =F138 -> 0.25119123 | G21: =G138 -> 0.37134543 | H21: =H138 -> 0.41710039 | I21: =I138 -> 0.4377409 | J21: =J138 -> 0.44939791 | K21: =K138 -> 0.45681816 | ... N21: =N138 -> 0.46828842
D23: 24年 | E23: 25年 | F23: 26年 | G23: 27年 | H23: 28年 | I23: 29年 | J23: 30年 | K23: 31年 | L23: 32年 | M23: 33年 | N23: 34年
A24: スタンド計 | B24: 売上高計 | D24: =SUM(D40:D42) -> 52989.912 | E24: =SUM(E40:E42) -> 109073.34 | F24: =SUM(F40:F42) -> 219913.87 | G24: =SUM(G40:G42) -> 376650.2 | H24: =SUM(H40:H42) -> 551428.33 | I24: =SUM(I40:I42) -> 714804.99 | J24: =SUM(J40:J42) -> 868148.37 | K24: =SUM(K40:K42) -> 1012662.4 | ... N24: =SUM(N40:N42) -> 1403203.6
B25: 粗利 | D25: =SUM(D58:D60) -> 36161.31 | E25: =SUM(E58:E60) -> 80975.961 | F25: =SUM(F58:F60) -> 171142.45 | G25: =SUM(G58:G60) -> 298639.81 | H25: =SUM(H58:H60) -> 442063.91 | I25: =SUM(I58:I60) -> 577849.03 | J25: =SUM(J58:J60) -> 706911.84 | K25: =SUM(K58:K60) -> 830059.03 | ... N25: =SUM(N58:N60) -> 1170689.9
B26: 限界利益 | D26: =SUM(D76:D78) -> 27230.486 | E26: =SUM(E76:E78) -> 50861.095 | F26: =SUM(F76:F78) -> 96267.551 | G26: =SUM(G76:G78) -> 160211.39 | H26: =SUM(H76:H78) -> 229653.75 | I26: =SUM(I76:I78) -> 292131.8 | J26: =SUM(J76:J78) -> 348481.28 | K26: =SUM(K76:K78) -> 399437.59 | ... N26: =SUM(N76:N78) -> 526040.43
C27: 限界利益率 | D27: =D26/D24 -> 0.51388056 | E27: =E26/E24 -> 0.46630182 | F27: =F26/F24 -> 0.43775117 | G27: =G26/G24 -> 0.42535858 | H27: =H26/H24 -> 0.41647071 | I27: =I26/I24 -> 0.40868741 | J27: =J26/J24 -> 0.40140751 | K27: =K26/K24 -> 0.39444298 | ... N27: =N26/N24 -> 0.37488531
B28: 直接利益 | D28: =SUM(D94:D96) -> 18590.156 | E28: =SUM(E94:E96) -> 7473.3436 | F28: =SUM(F94:F96) -> 29855.53 | G28: =SUM(G94:G96) -> 70383.13 | H28: =SUM(H94:H96) -> 124351.98 | I28: =SUM(I94:I96) -> 171086.39 | J28: =SUM(J94:J96) -> 211580.21 | K28: =SUM(K94:K96) -> 246618.63 | ... N28: =SUM(N94:N96) -> 325257.97
C29: 直接利益率 | D29: =D28/D24 -> 0.35082444 | E29: =E28/E24 -> 0.068516686 | F29: =F28/F24 -> 0.13576011 | G29: =G28/G24 -> 0.18686604 | H29: =H28/H24 -> 0.22550887 | I29: =I28/I24 -> 0.23934694 | J29: =J28/J24 -> 0.24371434 | K29: =K28/K24 -> 0.24353488 | ... N29: =N28/N24 -> 0.2317967
B30: 営業利益 | D30: =SUM(D112:D114) -> 18379.288 | E30: =SUM(E112:E114) -> 2869.7817 | F30: =SUM(F112:F114) -> 15603.177 | G30: =SUM(G112:G114) -> 42953.739 | H30: =SUM(H112:H114) -> 82940.966 | I30: =SUM(I112:I114) -> 117371.55 | J30: =SUM(J112:J114) -> 147038 | K30: =SUM(K112:K114) -> 172548.34 | ... N30: =SUM(N112:N114) -> 228931.3
C31: 営業利益率 | D31: =D30/D24 -> 0.34684503 | E31: =E30/E24 -> 0.02631057 | F31: =F30/F24 -> 0.070951311 | G31: =G30/G24 -> 0.11404146 | H31: =H30/H24 -> 0.15041115 | I31: =I30/I24 -> 0.1642008 | J31: =J30/J24 -> 0.16936967 | K31: =K30/K24 -> 0.17039078 | ... N31: =N30/N24 -> 0.16314902
D37: 24年 | E37: 25年 | F37: 26年 | G37: 27年 | H37: 28年 | I37: 29年 | J37: 30年 | K37: 31年 | L37: 32年 | M37: 33年 | N37: 34年
B38: 売上高計 | C38: サービス計 | D38: =SUM(D39:D46) -> 213867.54 | E38: =SUM(E39:E46) -> 398510.32 | F38: =SUM(F39:F46) -> 887604.91 | G38: =SUM(G39:G46) -> 1570742.7 | H38: =SUM(H39:H46) -> 2355042.8 | I38: =SUM(I39:I46) -> 3085274.9 | J38: =SUM(J39:J46) -> 3765793.8 | K38: =SUM(K39:K46) -> 4400581.2 | ... N38: =SUM(N39:N46) -> 6065468.6
B39: 売上高計 | C39: アプリ | D39: =売上高!E5 -> 31621.632 | E39: =売上高!F5 -> 160180.98 | F39: =売上高!G5 -> 538435.04 | G39: =売上高!H5 -> 1064836.5 | H39: =売上高!I5 -> 1674358.4 | I39: =売上高!J5 -> 2241213.9 | J39: =売上高!K5 -> 2768389.5 | K39: =売上高!L5 -> 3258662.7 | ... N39: =売上高!O5 -> 4533009
B40: 売上高計 | C40: スタンド（宅急便） | D40: =売上高!E6 -> 49489.56 | E40: =売上高!F6 -> 52260.975 | F40: =売上高!G6 -> 45989.658 | G40: =売上高!H6 -> 40470.899 | H40: =売上高!I6 -> 35614.391 | I40: =売上高!J6 -> 31340.664 | J40: =売上高!K6 -> 27579.785 | K40: =売上高!L6 -> 24270.211 | ... N40: =売上高!O6 -> 16539.469
B41: 売上高計 | C41: スタンド（ＦＳ） | D41: =売上高!E7 -> 1506.204 | E41: =売上高!F7 -> 32882.585 | F41: =売上高!G7 -> 101802.52 | G41: =売上高!H7 -> 195924.22 | H41: =売上高!I7 -> 295792.94 | I41: =売上高!J7 -> 383677.41 | J41: =売上高!K7 -> 461015.75 | K41: =売上高!L7 -> 529073.48 | ... N41: =売上高!O7 -> 688047.64
B42: 売上高計 | C42: スタンド（社外） | D42: =売上高!E8 -> 1994.148 | E42: =売上高!F8 -> 23929.776 | F42: =売上高!G8 -> 72121.686 | G42: =売上高!H8 -> 140255.08 | H42: =売上高!I8 -> 220021 | I42: =売上高!J8 -> 299786.92 | J42: =売上高!K8 -> 379552.84 | K42: =売上高!L8 -> 459318.76 | ... N42: =売上高!O8 -> 698616.52
B43: 売上高計 | C43: フロー（セミナー等） | D43: =売上高!E9 -> 45120 | E43: =売上高!F9 -> 45120 | F43: =売上高!G9 -> 45120 | G43: =売上高!H9 -> 45120 | H43: =売上高!I9 -> 45120 | I43: =売上高!J9 -> 45120 | J43: =売上高!K9 -> 45120 | K43: =売上高!L9 -> 45120 | ... N43: =売上高!O9 -> 45120
B44: 売上高計 | C44: ECストア | D44: =売上高!E10 -> 937 | E44: =売上高!F10 -> 937 | F44: =売上高!G10 -> 937 | G44: =売上高!H10 -> 937 | H44: =売上高!I10 -> 937 | I44: =売上高!J10 -> 937 | J44: =売上高!K10 -> 937 | K44: =売上高!L10 -> 937 | ... N44: =売上高!O10 -> 937
B45: 売上高計 | C45: 卸売 | D45: =売上高!E11 -> 49598 | E45: =売上高!F11 -> 49598 | F45: =売上高!G11 -> 49598 | G45: =売上高!H11 -> 49598 | H45: =売上高!I11 -> 49598 | I45: =売上高!J11 -> 49598 | J45: =売上高!K11 -> 49598 | K45: =売上高!L11 -> 49598 | ... N45: =売上高!O11 -> 49598
B46: 売上高計 | C46: 企業内手売 | D46: =売上高!E12 -> 33601 | E46: =売上高!F12 -> 33601 | F46: =売上高!G12 -> 33601 | G46: =売上高!H12 -> 33601 | H46: =売上高!I12 -> 33601 | I46: =売上高!J12 -> 33601 | J46: =売上高!K12 -> 33601 | K46: =売上高!L12 -> 33601 | ... N46: =売上高!O12 -> 33601
B47: 原価 | C47: サービス計 | D47: =SUM(D48:D55) -> 72049.102 | E47: =SUM(E48:E55) -> 83317.875 | F47: =SUM(F48:F55) -> 103991.92 | G47: =SUM(G48:G55) -> 133230.89 | H47: =SUM(H48:H55) -> 164584.92 | I47: =SUM(I48:I55) -> 192176.46 | J47: =SUM(J48:J55) -> 216457.03 | K47: =SUM(K48:K55) -> 237823.92 | ... N47: =SUM(N48:N55) -> 287734.25
B48: 原価 | C48: アプリ | D48: =D39*原価・変動費!E6 -> 0 | E48: =E39*原価・変動費!F6 -> 0 | F48: =F39*原価・変動費!G6 -> 0 | G48: =G39*原価・変動費!H6 -> 0 | H48: =H39*原価・変動費!I6 -> 0 | I48: =I39*原価・変動費!J6 -> 0 | J48: =J39*原価・変動費!K6 -> 0 | K48: =K39*原価・変動費!L6 -> 0 | ... N48: =N39*原価・変動費!O6 -> 0
...

Sheet 売上高
A1: 単位：千円
E2: ※ベンチマーク値
E3: 24年 | F3: 25年 | G3: 26年 | H3: 27年 | I3: 28年 | J3: 29年 | K3: 30年 | L3: 31年 | M3: 32年 | N3: 33年 | O3: 34年
B4: 売上高 | C4: 合計 | D4: サービス計 | E4: =SUM(E5:E12) -> 213867.54 | F4: =SUM(F5:F12) -> 398510.32 | G4: =SUM(G5:G12) -> 887604.91 | H4: =SUM(H5:H12) -> 1570742.7 | I4: =SUM(I5:I12) -> 2355042.8 | J4: =SUM(J5:J12) -> 3085274.9 | K4: =SUM(K5:K12) -> 3765793.8 | L4: =SUM(L5:L12) -> 4400581.2 | ... O4: =SUM(O5:O12) -> 6065468.6
D5: アプリ | E5: =E32+E59 -> 31621.632 | F5: =F32+F59 -> 160180.98 | G5: =G32+G59 -> 538435.04 | H5: =H32+H59 -> 1064836.5 | I5: =I32+I59 -> 1674358.4 | J5: =J32+J59 -> 2241213.9 | K5: =K32+K59 -> 2768389.5 | L5: =L32+L59 -> 3258662.7 | ... O5: =O32+O59 -> 4533009
D6: スタンド（宅急便） | E6: =E33+E60 -> 49489.56 | F6: =F33+F60 -> 52260.975 | G6: =G33+G60 -> 45989.658 | H6: =H33+H60 -> 40470.899 | I6: =I33+I60 -> 35614.391 | J6: =J33+J60 -> 31340.664 | K6: =K33+K60 -> 27579.785 | L6: =L33+L60 -> 24270.211 | ... O6: =O33+O60 -> 16539.469
D7: スタンド（ＦＳ） | E7: =E34+E61 -> 1506.204 | F7: =F34+F61 -> 32882.585 | G7: =G34+G61 -> 101802.52 | H7: =H34+H61 -> 195924.22 | I7: =I34+I61 -> 295792.94 | J7: =J34+J61 -> 383677.41 | K7: =K34+K61 -> 461015.75 | L7: =L34+L61 -> 529073.48 | ... O7: =O34+O61 -> 688047.64
D8: スタンド（社外） | E8: =E35+E62 -> 1994.148 | F8: =F35+F62 -> 23929.776 | G8: =G35+G62 -> 72121.686 | H8: =H35+H62 -> 140255.08 | I8: =I35+I62 -> 220021 | J8: =J35+J62 -> 299786.92 | K8: =K35+K62 -> 379552.84 | L8: =L35+L62 -> 459318.76 | ... O8: =O35+O62 -> 698616.52
D9: フロー（セミナー等） | E9: =E36+E63 -> 45120 | F9: =F36+F63 -> 45120 | G9: =G36+G63 -> 45120 | H9: =H36+H63 -> 45120 | I9: =I36+I63 -> 45120 | J9: =J36+J63 -> 45120 | K9: =K36+K63 -> 45120 | L9: =L36+L63 -> 45120 | ... O9: =O36+O63 -> 45120
D10: ECストア | E10: =E37 -> 937 | F10: =F37 -> 937 | G10: =G37 -> 937 | H10: =H37 -> 937 | I10: =I37 -> 937 | J10: =J37 -> 937 | K10: =K37 -> 937 | L10: =L37 -> 937 | ... O10: =O37 -> 937
D11: 卸売 | E11: =E38 -> 49598 | F11: =F38 -> 49598 | G11: =G38 -> 49598 | H11: =H38 -> 49598 | I11: =I38 -> 49598 | J11: =J38 -> 49598 | K11: =K38 -> 49598 | L11: =L38 -> 49598 | ... O11: =O38 -> 49598
D12: 企業内手売 | E12: =E39 -> 33601 | F12: =F39 -> 33601 | G12: =G39 -> 33601 | H12: =H39 -> 33601 | I12: =I39 -> 33601 | J12: =J39 -> 33601 | K12: =K39 -> 33601 | L12: =L39 -> 33601 | ... O12: =O39 -> 33601
C13: Web | E13: =E40+E64 -> 17118.456 | F13: =F40+F64 -> 278489.78 | G13: =G40+G64 -> 549162.91 | H13: =H40+H64 -> 862671.85 | I13: =I40+I64 -> 1187790.7 | J13: =J40+J64 -> 1491614.5 | K13: =K40+K64 -> 1775905.1 | L13: =L40+L64 -> 2042268.2 | ... O13: =O40+O64 -> 2747814.9
D14: アプリ | E14: =E41+E65 -> 3720.192 | F14: =F41+F65 -> 132520.98 | G14: =G41+G65 -> 323939.84 | H14: =H41+H65 -> 544367.93 | I14: =I41+I65 -> 771126.71 | J14: =J41+J65 -> 982012.38 | K14: =K41+K65 -> 1178136.1 | L14: =L41+L65 -> 1360531.1 | ... O14: =O41+O65 -> 1834622.6
D15: スタンド（宅急便） | E15: =E42+E66 -> 9897.912 | F15: =F42+F66 -> 52260.975 | G15: =G42+G66 -> 45989.658 | H15: =H42+H66 -> 40470.899 | I15: =I42+I66 -> 35614.391 | J15: =J42+J66 -> 31340.664 | K15: =K42+K66 -> 27579.785 | L15: =L42+L66 -> 24270.211 | ... O15: =O42+O66 -> 16539.469
D16: スタンド（ＦＳ） | E16: =E43+E67 -> 1506.204 | F16: =F43+F67 -> 26319.839 | G16: =G43+G67 -> 71962.468 | H16: =H43+H67 -> 122370.17 | I16: =I43+I67 -> 172409.49 | J16: =J43+J67 -> 216444.09 | K16: =K43+K67 -> 255194.53 | L16: =L43+L67 -> 289294.93 | ... O16: =O43+O67 -> 368949.08
D17: スタンド（社外） | E17: =E44+E68 -> 1994.148 | F17: =F44+F68 -> 22267.986 | G17: =G44+G68 -> 62150.946 | H17: =H44+H68 -> 110342.86 | I17: =I44+I68 -> 163520.14 | J17: =J44+J68 -> 216697.42 | K17: =K44+K68 -> 269874.7 | L17: =L44+L68 -> 323051.98 | ... O17: =O44+O68 -> 482583.82
D18: フロー（セミナー等） | E18: =E45+E69 -> 0 | F18: =F45+F69 -> 45120 | G18: =G45+G69 -> 45120 | H18: =H45+H69 -> 45120 | I18: =I45+I69 -> 45120 | J18: =J45+J69 -> 45120 | K18: =K45+K69 -> 45120 | L18: =L45+L69 -> 45120 | ... O18: =O45+O69 -> 45120
C19: 法人 | E19: =E46+E70 -> 0 | F19: =F46+F70 -> 29013.51 | G19: =G46+G70 -> 216908.65 | H19: =H46+H70 -> 541876.59 | I19: =I46+I70 -> 952292.87 | J19: =J46+J70 -> 1334437.3 | K19: =K46+K70 -> 1690457.3 | L19: =L46+L70 -> 2022330 | ... O19: =O46+O70 -> 2890567.7
D20: アプリ | E20: =E47+E71 -> 0 | F20: =F47+F71 -> 25200 | G20: =G47+G71 -> 194544 | H20: =H47+H71 -> 476269.92 | I20: =I47+I71 -> 832019.03 | J20: =J47+J71 -> 1162865.7 | K20: =K47+K71 -> 1470553.1 | L20: =L47+L71 -> 1756702.4 | ... O20: =O47+O71 -> 2500477.9
D21: スタンド（宅急便） | E21: =E48+E72 -> 0 | F21: =F48+F72 -> 0 | G21: =G48+G72 -> 0 | H21: =H48+H72 -> 0 | I21: =I48+I72 -> 0 | J21: =J48+J72 -> 0 | K21: =K48+K72 -> 0 | L21: =L48+L72 -> 0 | ... O21: =O48+O72 -> 0
D22: スタンド（ＦＳ） | E22: =E49+E73 -> 0 | F22: =F49+F73 -> 2151.72 | G22: =G49+G73 -> 12393.907 | H22: =H49+H73 -> 35694.453 | I22: =I49+I73 -> 63772.987 | J22: =J49+J73 -> 88482.098 | K22: =K49+K73 -> 110226.11 | L22: =L49+L73 -> 129360.85 | ... O22: =O49+O73 -> 174057.14
D23: スタンド（社外） | E23: =E50+E74 -> 0 | F23: =F50+F74 -> 1661.79 | G23: =G50+G74 -> 9970.74 | H23: =H50+H74 -> 29912.22 | I23: =I50+I74 -> 56500.86 | J23: =J50+J74 -> 83089.5 | K23: =K50+K74 -> 109678.14 | L23: =L50+L74 -> 136266.78 | ... O23: =O50+O74 -> 216032.7
D24: フロー（セミナー等） | E24: =E51+E75 -> 0 | F24: =F51+F75 -> 0 | G24: =G51+G75 -> 0 | H24: =H51+H75 -> 0 | I24: =I51+I75 -> 0 | J24: =J51+J75 -> 0 | K24: =K51+K75 -> 0 | L24: =L51+L75 -> 0 | ... O24: =O51+O75 -> 0
C25: 代理店 | E25: =E52+E76 -> 0 | F25: =F52+F76 -> 6871.026 | G25: =G52+G76 -> 37397.346 | H25: =H52+H76 -> 82058.215 | I25: =I52+I76 -> 130823.18 | J25: =J52+J76 -> 175087.05 | K25: =K52+K76 -> 215295.41 | L25: =L52+L76 -> 251847 | ... O25: =O52+O76 -> 342949.91
D26: アプリ | E26: =E53+E77 -> 0 | F26: =F53+F77 -> 2460 | G26: =G53+G77 -> 19951.2 | H26: =H53+H77 -> 44198.616 | I26: =I53+I77 -> 71212.713 | J26: =J53+J77 -> 96335.823 | K26: =K53+K77 -> 119700.32 | L26: =L53+L77 -> 141429.29 | ... O26: =O53+O77 -> 197908.49
D27: スタンド（宅急便） | E27: =E54+E78 -> 0 | F27: =F54+F78 -> 0 | G27: =G54+G78 -> 0 | H27: =H54+H78 -> 0 | I27: =I54+I78 -> 0 | J27: =J54+J78 -> 0 | K27: =K54+K78 -> 0 | L27: =L54+L78 -> 0 | ... O27: =O54+O78 -> 0
D28: スタンド（ＦＳ） | E28: =E55+E79 -> 0 | F28: =F55+F79 -> 4411.026 | G28: =G55+G79 -> 17446.146 | H28: =H55+H79 -> 37859.599 | I28: =I55+I79 -> 59610.466 | J28: =J55+J79 -> 78751.228 | K28: =K55+K79 -> 95595.099 | L28: =L55+L79 -> 110417.71 | ... O28: =O55+O79 -> 145041.42
D29: スタンド（社外） | E29: =E56+E80 -> 0 | F29: =F56+F80 -> 0 | G29: =G56+G80 -> 0 | H29: =H56+H80 -> 0 | I29: =I56+I80 -> 0 | J29: =J56+J80 -> 0 | K29: =K56+K80 -> 0 | L29: =L56+L80 -> 0 | ... O29: =O56+O80 -> 0
D30: フロー（セミナー等） | E30: =E57+E81 -> 0 | F30: =F57+F81 -> 0 | G30: =G57+G81 -> 0 | H30: =H57+H81 -> 0 | I30: =I57+I81 -> 0 | J30: =J57+J81 -> 0 | K30: =K57+K81 -> 0 | L30: =L57+L81 -> 0 | ... O30: =O57+O81 -> 0
C31: 既存 | D31: サービス計 | E31: =SUM(E32:E39) -> 196749.09 | F31: =SUM(F32:F39) -> 218371.89 | G31: =SUM(G32:G39) -> 580586.26 | H31: =SUM(H32:H39) -> 1099224.6 | I31: =SUM(I32:I39) -> 1883524.7 | J31: =SUM(J32:J39) -> 2613756.8 | K31: =SUM(K32:K39) -> 3294275.7 | L31: =SUM(L32:L39) -> 3929063.1 | ... O31: =SUM(O32:O39) -> 5593950.5
D32: アプリ | E32: =契約数!E8*客単価!E5 -> 27901.44 | F32: =F41+F47+F53 -> 30215.7 | G32: =G41+G47+G53 -> 305928.8 | H32: =H41+H47+H53 -> 698828.78 | I32: =I41+I47+I53 -> 1308350.8 | J32: =J41+J47+J53 -> 1875206.2 | K32: =K41+K47+K53 -> 2402381.8 | L32: =L41+L47+L53 -> 2892655.1 | M32: =M41+M47+M53 -> 3348609.2 | ... O32: =O41+O47+O53 -> 4167001.3
D33: スタンド（宅急便） | E33: =契約数!E9*客単価!E6 -> 39591.648 | F33: =F42+F48+F54 -> 52260.975 | G33: =G42+G48+G54 -> 45989.658 | H33: =H42+H48+H54 -> 40470.899 | I33: =I42+I48+I54 -> 35614.391 | J33: =J42+J48+J54 -> 31340.664 | K33: =K42+K48+K54 -> 27579.785 | L33: =L42+L48+L54 -> 24270.211 | M33: =M42+M48+M54 -> 21357.785 | ... O33: =O42+O48+O54 -> 16539.469
D34: スタンド（ＦＳ） | E34: =契約数!E10*客単価!E7 -> 0 | F34: =F43+F49+F55 -> 2650.919 | G34: =G43+G49+G55 -> 55540.541 | H34: =H43+H49+H55 -> 130296.76 | I34: =I43+I49+I55 -> 230165.48 | J34: =J43+J49+J55 -> 318049.95 | K34: =K43+K49+K55 -> 395388.29 | L34: =L43+L49+L55 -> 463446.02 | M34: =M43+M49+M55 -> 523336.83 | ... O34: =O43+O49+O55 -> 622420.18
D35: スタンド（社外） | E35: =契約数!E11*客単価!E8 -> 0 | F35: =F44+F50+F56 -> 3988.296 | G35: =G44+G50+G56 -> 43871.256 | H35: =H44+H50+H56 -> 100372.12 | I35: =I44+I50+I56 -> 180138.04 | J35: =J44+J50+J56 -> 259903.96 | K35: =K44+K50+K56 -> 339669.88 | L35: =L44+L50+L56 -> 419435.8 | M35: =M44+M50+M56 -> 499201.72 | ... O35: =O44+O50+O56 -> 658733.56
D36: フロー（セミナー等） | E36: =契約数!E12*客単価!E9 -> 45120 | F36: =F45+F51+F57 -> 45120 | G36: =G45+G51+G57 -> 45120 | H36: =H45+H51+H57 -> 45120 | I36: =I45+I51+I57 -> 45120 | J36: =J45+J51+J57 -> 45120 | K36: =K45+K51+K57 -> 45120 | L36: =L45+L51+L57 -> 45120 | M36: =M45+M51+M57 -> 45120 | ... O36: =O45+O51+O57 -> 45120
D37: ECストア | E37: 937 | F37: =E37 -> 937 | G37: =F37 -> 937 | H37: =G37 -> 937 | I37: =H37 -> 937 | J37: =I37 -> 937 | K37: =J37 -> 937 | L37: =K37 -> 937 | M37: =L37 -> 937 | ... O37: =N37 -> 937 | Q37: ＊ECストアは計画上はステイ
D38: 卸売 | E38: 49598 | F38: =E38 -> 49598 | G38: =F38 -> 49598 | H38: =G38 -> 49598 | I38: =H38 -> 49598 | J38: =I38 -> 49598 | K38: =J38 -> 49598 | L38: =K38 -> 49598 | M38: =L38 -> 49598 | ... O38: =N38 -> 49598 | Q38: ＊卸売は計画上はステイ
D39: 企業内手売 | E39: 33601 | F39: =E39 -> 33601 | G39: =F39 -> 33601 | H39: =G39 -> 33601 | I39: =H39 -> 33601 | J39: =I39 -> 33601 | K39: =J39 -> 33601 | L39: =K39 -> 33601 | M39: =L39 -> 33601 | ... O39: =N39 -> 33601 | Q39: ＊企業内手売は計画上はステイ
C40: Web | E40: =SUM(E41:E45) -> 0 | F40: =SUM(F41:F45) -> 134235.89 | G40: =SUM(G41:G45) -> 378681.04 | H40: =SUM(H41:H45) -> 652848.01 | I40: =SUM(I41:I45) -> 977966.88 | J40: =SUM(J41:J45) -> 1281790.7 | K40: =SUM(K41:K45) -> 1566081.2 | L40: =SUM(L41:L45) -> 1832444.3 | ... O40: =SUM(O41:O45) -> 2537991.1
...

Sheet Input＞＞

Sheet 契約数
E3: 24年 | F3: 25年 | G3: 26年 | H3: 27年 | I3: 28年 | J3: 29年 | K3: 30年 | L3: 31年 | M3: 32年 | N3: 33年 | O3: 34年
B4: 契約数 | E4: =E5+E6 -> 290 | F4: =F5+F6 -> 653.27 | G4: =G5+G6 -> 1191.1311 | H4: =H5+H6 -> 1921.0235 | I4: =I5+I6 -> 2592.8073 | J4: =J5+J6 -> 3212.3999 | K4: =K5+K6 -> 3785.0828 | L4: =L5+L6 -> 4315.5722 | ... O4: =O5+O6 -> 5693.8395
B5: 契約数 | C5: ストック | E5: =SUM(E8:E11)+SUM(E29:E32) -> 170 | F5: =SUM(F8:F11)+SUM(F29:F32) -> 533.27 | G5: =SUM(G8:G11)+SUM(G29:G32) -> 1071.1311 | H5: =SUM(H8:H11)+SUM(H29:H32) -> 1801.0235 | I5: =SUM(I8:I11)+SUM(I29:I32) -> 2472.8073 | J5: =SUM(J8:J11)+SUM(J29:J32) -> 3092.3999 | K5: =SUM(K8:K11)+SUM(K29:K32) -> 3665.0828 | L5: =SUM(L8:L11)+SUM(L29:L32) -> 4195.5722 | ... O5: =SUM(O8:O11)+SUM(O29:O32) -> 5573.8395
B6: 契約数 | C6: フロー | E6: =E12+E33 -> 120 | F6: =F12+F33 -> 120 | G6: =G12+G33 -> 120 | H6: =H12+H33 -> 120 | I6: =I12+I33 -> 120 | J6: =J12+J33 -> 120 | K6: =K12+K33 -> 120 | L6: =L12+L33 -> 120 | ... O6: =O12+O33 -> 120
B7: 契約数 | C7: 既存 | E7: =SUM(E8:E12) -> 227 | F7: =SUM(F8:F11) -> 151.27 | G7: =SUM(G8:G11) -> 486.1311 | H7: =SUM(H8:H11) -> 981.02352 | I7: =SUM(I8:I11) -> 1652.8073 | J7: =SUM(J8:J11) -> 2272.3999 | K7: =SUM(K8:K11) -> 2845.0828 | L7: =SUM(L8:L11) -> 3375.5722 | M7: =SUM(M8:M11) -> 3868.0822 | ... O7: =SUM(O8:O11) -> 4753.8395
B8: 契約数 | D8: アプリ | E8: =E13+E18+E23 -> 15 | F8: =F13+F18+F23 -> 17.67 | G8: =G13+G18+G23 -> 166.1631 | H8: =H13+H18+H23 -> 377.73168 | I8: =I13+I18+I23 -> 658.19047 | J8: =J13+J18+J23 -> 919.01713 | K8: =K13+K18+K23 -> 1161.5859 | L8: =L13+L18+L23 -> 1387.1749 | ... O8: =O13+O18+O23 -> 1973.5387
B9: 契約数 | D9: スタンド（宅急便） | E9: =E14+E19+E24 -> 92 | F9: =F14+F19+F24 -> 121.44 | G9: =G14+G19+G24 -> 106.8672 | H9: =H14+H19+H24 -> 94.043136 | I9: =I14+I19+I24 -> 82.75796 | J9: =J14+J19+J24 -> 72.827005 | K9: =K14+K19+K24 -> 64.087764 | L9: =L14+L19+L24 -> 56.397232 | ... O9: =O14+O19+O24 -> 38.433135
B10: 契約数 | D10: スタンド（ＦＳ） | E10: =E15+E20+E25 -> 0 | F10: =F15+F20+F25 -> 6.16 | G10: =G15+G20+G25 -> 147.1008 | H10: =H15+H20+H25 -> 358.2487 | I10: =I15+I20+I25 -> 640.85886 | J10: =J15+J20+J25 -> 889.5558 | K10: =K15+K20+K25 -> 1108.4091 | L10: =L15+L20+L25 -> 1301 | ... O10: =O15+O20+O25 -> 1750.8677
B11: 契約数 | D11: スタンド（社外） | E11: =E16+E21+E26 -> 0 | F11: =F16+F21+F26 -> 6 | G11: =G16+G21+G26 -> 66 | H11: =H16+H21+H26 -> 151 | I11: =I16+I21+I26 -> 271 | J11: =J16+J21+J26 -> 391 | K11: =K16+K21+K26 -> 511 | L11: =L16+L21+L26 -> 631 | ... O11: =O16+O21+O26 -> 991
B12: 契約数 | D12: フロー（セミナー等） | E12: =E17+E22+E27 -> 120 | F12: =F17+F22+F27 -> 120 | G12: =G17+G22+G27 -> 120 | H12: =H17+H22+H27 -> 120 | I12: =I17+I22+I27 -> 120 | J12: =J17+J22+J27 -> 120 | K12: =K17+K22+K27 -> 120 | L12: =L17+L22+L27 -> 120 | ... O12: =O17+O22+O27 -> 120
B13: 契約数 | C13: Web | D13: アプリ | E13: 15 | F13: =(E13+E34)*E50 -> 17.67 | G13: =(F13+F34)*F50 -> 118.7331 | H13: =(G13+G34)*G50 -> 231.32178 | I13: =(H13+H34)*H50 -> 363.92926 | J13: =(I13+I34)*I50 -> 487.25421 | K13: =(J13+J34)*J50 -> 601.94642 | L13: =(K13+K34)*K50 -> 708.61017 | M13: =(L13+L34)*L50 -> 807.80745 | ... O13: =(N13+N34)*N50 -> 985.85667
B14: 契約数 | D14: スタンド（宅急便） | E14: 92 | F14: =(E14+E35)*E51 -> 121.44 | G14: =(F14+F35)*F51 -> 106.8672 | H14: =(G14+G35)*G51 -> 94.043136 | I14: =(H14+H35)*H51 -> 82.75796 | J14: =(I14+I35)*I51 -> 72.827005 | K14: =(J14+J35)*J51 -> 64.087764 | L14: =(K14+K35)*K51 -> 56.397232 | M14: =(L14+L35)*L51 -> 49.629564 | ... O14: =(N14+N35)*N51 -> 38.433135
B15: 契約数 | D15: スタンド（ＦＳ） | E15: 0 | F15: =(E15+E36)*E52 -> 6.16 | G15: =(F15+F36)*F52 -> 102.2208 | H15: =(G15+G36)*G52 -> 204.3543 | I15: =(H15+H36)*H52 -> 320.63179 | J15: =(I15+I36)*I52 -> 422.95597 | K15: =(J15+J36)*J52 -> 513.00126 | L15: =(K15+K36)*K52 -> 592.24111 | M15: =(L15+L36)*L52 -> 661.97217 | ... O15: =(N15+N36)*N52 -> 777.33525
B16: 契約数 | D16: スタンド（社外） | E16: 0 | F16: =(E16+E37)*E53 -> 6 | G16: =(F16+F37)*F53 -> 61 | H16: =(G16+G37)*G53 -> 126 | I16: =(H16+H37)*H53 -> 206 | J16: =(I16+I37)*I53 -> 286 | K16: =(J16+J37)*J53 -> 366 | L16: =(K16+K37)*K53 -> 446 | M16: =(L16+L37)*L53 -> 526 | ... O16: =(N16+N37)*N53 -> 686
B17: 契約数 | D17: フロー（セミナー等） | E17: 120 | F17: =(E17+E38)*E54 -> 120 | G17: =(F17+F38)*F54 -> 120 | H17: =(G17+G38)*G54 -> 120 | I17: =(H17+H38)*H54 -> 120 | J17: =(I17+I38)*I54 -> 120 | K17: =(J17+J38)*J54 -> 120 | L17: =(K17+K38)*K54 -> 120 | M17: =(L17+L38)*L54 -> 120 | ... O17: =(N17+N38)*N54 -> 120
B18: 契約数 | C18: 法人 | D18: アプリ | F18: =(E18+E39)*E50 -> 0 | G18: =(F18+F39)*F50 -> 9.3 | H18: =(G18+G39)*G50 -> 27.249 | I18: =(H18+H39)*H50 -> 62.54157 | J18: =(I18+I39)*I50 -> 95.36366 | K18: =(J18+J39)*J50 -> 125.8882 | L18: =(K18+K39)*K50 -> 154.27603 | M18: =(L18+L39)*L50 -> 180.67671 | ... O18: =(N18+N39)*N50 -> 228.06328
B19: 契約数 | D19: スタンド（宅急便） | F19: =(E19+E40)*E51 -> 0 | G19: =(F19+F40)*F51 -> 0 | H19: =(G19+G40)*G51 -> 0 | I19: =(H19+H40)*H51 -> 0 | J19: =(I19+I40)*I51 -> 0 | K19: =(J19+J40)*J51 -> 0 | L19: =(K19+K40)*K51 -> 0 | M19: =(L19+L40)*L51 -> 0 | ... O19: =(N19+N40)*N51 -> 0
B20: 契約数 | D20: スタンド（ＦＳ） | F20: =(E20+E41)*E52 -> 0 | G20: =(F20+F41)*F52 -> 8.8 | H20: =(G20+G41)*G52 -> 42.944 | I20: =(H20+H41)*H52 -> 108.19072 | J20: =(I20+I41)*I52 -> 165.60783 | K20: =(J20+J41)*J52 -> 216.13489 | L20: =(K20+K41)*K52 -> 260.59871 | M20: =(L20+L41)*L52 -> 299.72686 | ... O20: =(N20+N41)*N52 -> 364.46048
B21: 契約数 | D21: スタンド（社外） | F21: =(E21+E42)*E53 -> 0 | G21: =(F21+F42)*F53 -> 5 | H21: =(G21+G42)*G53 -> 25 | I21: =(H21+H42)*H53 -> 65 | J21: =(I21+I42)*I53 -> 105 | K21: =(J21+J42)*J53 -> 145 | L21: =(K21+K42)*K53 -> 185 | M21: =(L21+L42)*L53 -> 225 | ... O21: =(N21+N42)*N53 -> 305
B22: 契約数 | D22: フロー（セミナー等） | F22: =(E22+E43)*E54 -> 0 | G22: =(F22+F43)*F54 -> 0 | H22: =(G22+G43)*G54 -> 0 | I22: =(H22+H43)*H54 -> 0 | J22: =(I22+I43)*I54 -> 0 | K22: =(J22+J43)*J54 -> 0 | L22: =(K22+K43)*K54 -> 0 | M22: =(L22+L43)*L54 -> 0 | ... O22: =(N22+N43)*N54 -> 0
B23: 契約数 | C23: 代理店 | D23: アプリ | F23: =(E23+E44)*E50 -> 0 | G23: =(F23+F44)*F50 -> 38.13 | H23: =(G23+G44)*G50 -> 119.1609 | I23: =(H23+H44)*H50 -> 231.71964 | J23: =(I23+I44)*I50 -> 336.39926 | K23: =(J23+J44)*J50 -> 433.75131 | L23: =(K23+K44)*K50 -> 524.28872 | M23: =(L23+L44)*L50 -> 608.48851 | ... O23: =(N23+N44)*N50 -> 759.61871
B24: 契約数 | D24: スタンド（宅急便） | F24: =(E24+E45)*E51 -> 0 | G24: =(F24+F45)*F51 -> 0 | H24: =(G24+G45)*G51 -> 0 | I24: =(H24+H45)*H51 -> 0 | J24: =(I24+I45)*I51 -> 0 | K24: =(J24+J45)*J51 -> 0 | L24: =(K24+K45)*K51 -> 0 | M24: =(L24+L45)*L51 -> 0 | ... O24: =(N24+N45)*N51 -> 0
B25: 契約数 | D25: スタンド（ＦＳ） | F25: =(E25+E46)*E52 -> 0 | G25: =(F25+F46)*F52 -> 36.08 | H25: =(G25+G46)*G52 -> 110.9504 | I25: =(H25+H46)*H52 -> 212.03635 | J25: =(I25+I46)*I52 -> 300.99199 | K25: =(J25+J46)*J52 -> 379.27295 | L25: =(K25+K46)*K52 -> 448.1602 | M25: =(L25+L46)*L52 -> 508.78097 | ... O25: =(N25+N46)*N52 -> 609.07199
B26: 契約数 | D26: スタンド（社外） | F26: =(E26+E47)*E53 -> 0 | G26: =(F26+F47)*F53 -> 0 | H26: =(G26+G47)*G53 -> 0 | I26: =(H26+H47)*H53 -> 0 | J26: =(I26+I47)*I53 -> 0 | K26: =(J26+J47)*J53 -> 0 | L26: =(K26+K47)*K53 -> 0 | M26: =(L26+L47)*L53 -> 0 | ... O26: =(N26+N47)*N53 -> 0
B27: 契約数 | D27: フロー（セミナー等） | F27: =(E27+E48)*E54 -> 0 | G27: =(F27+F48)*F54 -> 0 | H27: =(G27+G48)*G54 -> 0 | I27: =(H27+H48)*H54 -> 0 | J27: =(I27+I48)*I54 -> 0 | K27: =(J27+J48)*J54 -> 0 | L27: =(K27+K48)*K54 -> 0 | M27: =(L27+L48)*L54 -> 0 | ... O27: =(N27+N48)*N54 -> 0
B28: 契約数 | C28: 新規 | E28: =SUM(E29:E33) -> 63 | F28: =SUM(F29:F33) -> 382 | G28: =SUM(G29:G33) -> 585 | H28: =SUM(H29:H33) -> 820 | I28: =SUM(I29:I33) -> 820 | J28: =SUM(J29:J33) -> 820 | K28: =SUM(K29:K33) -> 820 | L28: =SUM(L29:L33) -> 820 | ... O28: =SUM(O29:O33) -> 820
B29: 契約数 | D29: アプリ | E29: =E34+E39+E44 -> 4 | F29: =F34+F39+F44 -> 161 | G29: =G34+G39+G44 -> 240 | H29: =H34+H39+H44 -> 330 | I29: =I34+I39+I44 -> 330 | J29: =J34+J39+J44 -> 330 | K29: =K34+K39+K44 -> 330 | L29: =L34+L39+L44 -> 330 | ... O29: =O34+O39+O44 -> 330
B30: 契約数 | D30: スタンド（宅急便） | E30: =E35+E40+E45 -> 46 | F30: =F35+F40+F45 -> 0 | G30: =G35+G40+G45 -> 0 | H30: =H35+H40+H45 -> 0 | I30: =I35+I40+I45 -> 0 | J30: =J35+J40+J45 -> 0 | K30: =K35+K40+K45 -> 0 | L30: =L35+L40+L45 -> 0 | ... O30: =O35+O40+O45 -> 0
B31: 契約数 | D31: スタンド（ＦＳ） | E31: =E36+E41+E46 -> 7 | F31: =F36+F41+F46 -> 161 | G31: =G36+G41+G46 -> 260 | H31: =H36+H41+H46 -> 370 | I31: =I36+I41+I46 -> 370 | J31: =J36+J41+J46 -> 370 | K31: =K36+K41+K46 -> 370 | L31: =L36+L41+L46 -> 370 | ... O31: =O36+O41+O46 -> 370
B32: 契約数 | D32: スタンド（社外） | E32: =E37+E42+E47 -> 6 | F32: =F37+F42+F47 -> 60 | G32: =G37+G42+G47 -> 85 | H32: =H37+H42+H47 -> 120 | I32: =I37+I42+I47 -> 120 | J32: =J37+J42+J47 -> 120 | K32: =K37+K42+K47 -> 120 | L32: =L37+L42+L47 -> 120 | ... O32: =O37+O42+O47 -> 120
B33: 契約数 | D33: フロー（セミナー等） | E33: =E38+E43+E48 -> 0 | F33: =F38+F43+F48 -> 0 | G33: =G38+G43+G48 -> 0 | H33: =H38+H43+H48 -> 0 | I33: =I38+I43+I48 -> 0 | J33: =J38+J43+J48 -> 0 | K33: =K38+K43+K48 -> 0 | L33: =L38+L43+L48 -> 0 | ... O33: =O38+O43+O48 -> 0
B34: 契約数 | C34: Web | D34: アプリ | E34: 4 | F34: 110 | G34: 130 | H34: 160 | I34: 160 | J34: 160 | K34: 160 | L34: 160 | M34: 160 | N34: 160 | O34: 160
B35: 契約数 | D35: スタンド（宅急便） | E35: 46
B36: 契約数 | D36: スタンド（ＦＳ） | E36: 7 | F36: =F34 -> 110 | G36: =G34 -> 130 | H36: =H34 -> 160 | I36: =I34 -> 160 | J36: =J34 -> 160 | K36: =K34 -> 160 | L36: =L34 -> 160 | M36: =M34 -> 160 | ... O36: =O34 -> 160 | Q36: スタンド単独獲得は反映していない
B37: 契約数 | D37: スタンド（社外） | E37: 6 | F37: =F34*1/2 -> 55 | G37: =G34*1/2 -> 65 | H37: =H34*1/2 -> 80 | I37: =I34*1/2 -> 80 | J37: =J34*1/2 -> 80 | K37: =K34*1/2 -> 80 | L37: =L34*1/2 -> 80 | M37: =M34*1/2 -> 80 | ... O37: =O34*1/2 -> 80
B38: 契約数 | D38: フロー（セミナー等） | E38: 0
B39: 契約数 | C39: 法人 | D39: アプリ | F39: 10 | G39: 20 | H39: 40 | I39: 40 | J39: 40 | K39: 40 | L39: 40 | M39: 40 | N39: 40 | O39: 40
B40: 契約数 | D40: スタンド（宅急便）
B41: 契約数 | D41: スタンド（ＦＳ） | F41: 10 | G41: =G39*2 -> 40 | H41: =H39*2 -> 80 | I41: =I39*2 -> 80 | J41: =J39*2 -> 80 | K41: =K39*2 -> 80 | L41: =L39*2 -> 80 | M41: =M39*2 -> 80 | N41: =N39*2 -> 80 | O41: =O39*2 -> 80 | Q41: スタンド単独獲得は反映していない
B42: 契約数 | D42: スタンド（社外） | F42: =F41/2 -> 5 | G42: =G41/2 -> 20 | H42: =H41/2 -> 40 | I42: =I41/2 -> 40 | J42: =J41/2 -> 40 | K42: =K41/2 -> 40 | L42: =L41/2 -> 40 | M42: =M41/2 -> 40 | ... O42: =O41/2 -> 40
...

Sheet 客単価
A1: 単位：千円
E3: 24年 | F3: 25年 | G3: 26年 | H3: 27年 | I3: 28年 | J3: 29年 | K3: 30年 | L3: 31年 | M3: 32年 | N3: 33年 | O3: 34年
B4: 客単価
B5: 客単価 | C5: 既存 | D5: アプリ | E5: =155008*12/1000 -> 1860.096 | F5: =E5 -> 1860.096 | G5: =F5 -> 1860.096 | H5: =G5 -> 1860.096 | I5: =H5 -> 1860.096 | J5: =I5 -> 1860.096 | K5: =J5 -> 1860.096 | L5: =K5 -> 1860.096 | M5: =L5 -> 1860.096 | ... O5: =N5 -> 1860.096
B6: 客単価 | D6: スタンド（宅急便） | E6: =35862*12/1000 -> 430.344 | F6: =E6 -> 430.344 | G6: =F6 -> 430.344 | H6: =G6 -> 430.344 | I6: =H6 -> 430.344 | J6: =I6 -> 430.344 | K6: =J6 -> 430.344 | L6: =K6 -> 430.344 | M6: =L6 -> 430.344 | ... O6: =N6 -> 430.344
B7: 客単価 | D7: スタンド（ＦＳ） | E7: =35862*12/1000 -> 430.344 | F7: =E7 -> 430.344 | G7: =F7 -> 430.344 | H7: =G7 -> 430.344 | I7: =H7 -> 430.344 | J7: =I7 -> 430.344 | K7: =J7 -> 430.344 | L7: =K7 -> 430.344 | M7: =L7 -> 430.344 | ... O7: =N7 -> 430.344
B8: 客単価 | D8: スタンド（社外） | E8: =55393*12/1000 -> 664.716 | F8: =E8 -> 664.716 | G8: =F8 -> 664.716 | H8: =G8 -> 664.716 | I8: =H8 -> 664.716 | J8: =I8 -> 664.716 | K8: =J8 -> 664.716 | L8: =K8 -> 664.716 | M8: =L8 -> 664.716 | ... O8: =N8 -> 664.716
B9: 客単価 | D9: フロー（セミナー等） | E9: 376 | F9: =E9 -> 376 | G9: =F9 -> 376 | H9: =G9 -> 376 | I9: =H9 -> 376 | J9: =I9 -> 376 | K9: =J9 -> 376 | L9: =K9 -> 376 | M9: =L9 -> 376 | ... O9: =N9 -> 376
B10: 客単価 | C10: 新規
B11: 客単価 | C11: Web | D11: アプリ | F11: 1710 | G11: 1710 | H11: 1710 | I11: 1710 | J11: 1710 | K11: 1710 | L11: 1710 | M11: 1710 | N11: 1710 | O11: 1710 | Q11: 従業員数 | R11: 356 | S11: 人
B12: 客単価 | D12: スタンド（宅急便） | F12: =F6 -> 430.344 | G12: =G6 -> 430.344 | H12: =H6 -> 430.344 | I12: =I6 -> 430.344 | J12: =J6 -> 430.344 | K12: =K6 -> 430.344 | L12: =L6 -> 430.344 | M12: =M6 -> 430.344 | ... O12: =O6 -> 430.344 | Q12: 単価 | R12: 400 | S12: 円/月・人
B13: 客単価 | D13: スタンド（ＦＳ） | F13: =F7 -> 430.344 | G13: =G7 -> 430.344 | H13: =H7 -> 430.344 | I13: =I7 -> 430.344 | J13: =J7 -> 430.344 | K13: =K7 -> 430.344 | L13: =L7 -> 430.344 | M13: =M7 -> 430.344 | ... O13: =O7 -> 430.344
B14: 客単価 | D14: スタンド（社外） | F14: =F8 -> 664.716 | G14: =G8 -> 664.716 | H14: =H8 -> 664.716 | I14: =I8 -> 664.716 | J14: =J8 -> 664.716 | K14: =K8 -> 664.716 | L14: =L8 -> 664.716 | M14: =M8 -> 664.716 | ... O14: =O8 -> 664.716
B15: 客単価 | D15: フロー（セミナー等） | F15: =F9 -> 376 | G15: =G9 -> 376 | H15: =H9 -> 376 | I15: =I9 -> 376 | J15: =J9 -> 376 | K15: =K9 -> 376 | L15: =L9 -> 376 | M15: =M9 -> 376 | ... O15: =O9 -> 376
B16: 客単価 | C16: 法人 | D16: アプリ | F16: =$R$16*$R$17*12*1/2/1000 -> 5040 | G16: =$R$16*$R$17*12/1000 -> 10080 | H16: =$R$16*$R$17*12/1000 -> 10080 | I16: =$R$16*$R$17*12/1000 -> 10080 | J16: =$R$16*$R$17*12/1000 -> 10080 | K16: =$R$16*$R$17*12/1000 -> 10080 | L16: =$R$16*$R$17*12/1000 -> 10080 | M16: =$R$16*$R$17*12/1000 -> 10080 | N16: =$R$16*$R$17*12/1000 -> 10080 | O16: =$R$16*$R$17*12/1000 -> 10080 | Q16: 従業員数 | R16: 2100 | S16: 人
B17: 客単価 | D17: スタンド（宅急便） | F17: =F12 -> 430.344 | G17: =G12 -> 430.344 | H17: =H12 -> 430.344 | I17: =I12 -> 430.344 | J17: =J12 -> 430.344 | K17: =K12 -> 430.344 | L17: =L12 -> 430.344 | M17: =M12 -> 430.344 | ... O17: =O12 -> 430.344 | Q17: 単価 | R17: 400 | S17: 円/月・人
B18: 客単価 | D18: スタンド（ＦＳ） | F18: =F13 -> 430.344 | G18: =G13 -> 430.344 | H18: =H13 -> 430.344 | I18: =I13 -> 430.344 | J18: =J13 -> 430.344 | K18: =K13 -> 430.344 | L18: =L13 -> 430.344 | M18: =M13 -> 430.344 | ... O18: =O13 -> 430.344 | Q18: *25年は５0％OFFで計上
B19: 客単価 | D19: スタンド（社外） | F19: =F14 -> 664.716 | G19: =G14 -> 664.716 | H19: =H14 -> 664.716 | I19: =I14 -> 664.716 | J19: =J14 -> 664.716 | K19: =K14 -> 664.716 | L19: =L14 -> 664.716 | M19: =M14 -> 664.716 | ... O19: =O14 -> 664.716
B20: 客単価 | D20: フロー（セミナー等） | F20: =F15 -> 376 | G20: =G15 -> 376 | H20: =H15 -> 376 | I20: =I15 -> 376 | J20: =J15 -> 376 | K20: =K15 -> 376 | L20: =L15 -> 376 | M20: =M15 -> 376 | ... O20: =O15 -> 376
B21: 客単価 | C21: 代理店 | D21: アプリ | F21: =$R$21*$R$22*12*0.5/1000 -> 120 | G21: =$R$21*$R$22*12/1000 -> 240 | H21: =$R$21*$R$22*12/1000 -> 240 | I21: =$R$21*$R$22*12/1000 -> 240 | J21: =$R$21*$R$22*12/1000 -> 240 | K21: =$R$21*$R$22*12/1000 -> 240 | L21: =$R$21*$R$22*12/1000 -> 240 | M21: =$R$21*$R$22*12/1000 -> 240 | N21: =$R$21*$R$22*12/1000 -> 240 | O21: =$R$21*$R$22*12/1000 -> 240 | Q21: 従業員数 | R21: 80 | S21: 人
B22: 客単価 | D22: スタンド（宅急便） | F22: =F17/2 -> 215.172 | G22: =G17/2 -> 215.172 | H22: =H17/2 -> 215.172 | I22: =I17/2 -> 215.172 | J22: =J17/2 -> 215.172 | K22: =K17/2 -> 215.172 | L22: =L17/2 -> 215.172 | M22: =M17/2 -> 215.172 | ... O22: =O17/2 -> 215.172 | Q22: 単価 | R22: 250 | S22: 円/月・人
B23: 客単価 | D23: スタンド（ＦＳ） | F23: =F18/2 -> 215.172 | G23: =G18/2 -> 215.172 | H23: =H18/2 -> 215.172 | I23: =I18/2 -> 215.172 | J23: =J18/2 -> 215.172 | K23: =K18/2 -> 215.172 | L23: =L18/2 -> 215.172 | M23: =M18/2 -> 215.172 | ... O23: =O18/2 -> 215.172 | Q23: ※25年は半額CPを実施する
B24: 客単価 | D24: スタンド（社外） | F24: =F19/2 -> 332.358 | G24: =G19/2 -> 332.358 | H24: =H19/2 -> 332.358 | I24: =I19/2 -> 332.358 | J24: =J19/2 -> 332.358 | K24: =K19/2 -> 332.358 | L24: =L19/2 -> 332.358 | M24: =M19/2 -> 332.358 | ... O24: =O19/2 -> 332.358
B25: 客単価 | D25: フロー（セミナー等） | F25: =F20/2 -> 188 | G25: =G20/2 -> 188 | H25: =H20/2 -> 188 | I25: =I20/2 -> 188 | J25: =J20/2 -> 188 | K25: =K20/2 -> 188 | L25: =L20/2 -> 188 | M25: =M20/2 -> 188 | ... O25: =O20/2 -> 188

Sheet 原価・変動費
A1: 単位：％
E3: 24年 | F3: 25年 | G3: 26年 | H3: 27年 | I3: 28年 | J3: 29年 | K3: 30年 | L3: 31年 | M3: 32年 | N3: 33年 | O3: 34年
B4: 変動高比
C5: 原価
C6: 原価 | D6: アプリ | E6: 0 | F6: =E6 -> 0 | G6: =F6 -> 0 | H6: =G6 -> 0 | I6: =H6 -> 0 | J6: =I6 -> 0 | K6: =J6 -> 0 | L6: =K6 -> 0 | M6: =L6 -> 0 | ... O6: =N6 -> 0
C7: 原価 | D7: スタンド（宅急便） | E7: 0.33 | F7: =E7 -> 0.33 | G7: =F7 -> 0.33 | H7: =G7 -> 0.33 | I7: =H7 -> 0.33 | J7: =I7 -> 0.33 | K7: =J7 -> 0.33 | L7: =K7 -> 0.33 | M7: =L7 -> 0.33 | ... O7: =N7 -> 0.33
C8: 原価 | D8: スタンド（ＦＳ） | E8: 0.33 | F8: =E8 -> 0.33 | G8: =F8 -> 0.33 | H8: =G8 -> 0.33 | I8: =H8 -> 0.33 | J8: =I8 -> 0.33 | K8: =J8 -> 0.33 | L8: =K8 -> 0.33 | M8: =L8 -> 0.33 | ... O8: =N8 -> 0.33
C9: 原価 | D9: スタンド（社外） | E9: 0 | F9: =E9 -> 0 | G9: =F9 -> 0 | H9: =G9 -> 0 | I9: =H9 -> 0 | J9: =I9 -> 0 | K9: =J9 -> 0 | L9: =K9 -> 0 | M9: =L9 -> 0 | ... O9: =N9 -> 0
C10: 原価 | D10: フロー（セミナー等） | E10: 0 | F10: =E10 -> 0 | G10: =F10 -> 0 | H10: =G10 -> 0 | I10: =H10 -> 0 | J10: =I10 -> 0 | K10: =J10 -> 0 | L10: =K10 -> 0 | M10: =L10 -> 0 | ... O10: =N10 -> 0
C11: 原価 | D11: ＥＣストア | E11: 0.45 | F11: =E11 -> 0.45 | G11: =F11 -> 0.45 | H11: =G11 -> 0.45 | I11: =H11 -> 0.45 | J11: =I11 -> 0.45 | K11: =J11 -> 0.45 | L11: =K11 -> 0.45 | M11: =L11 -> 0.45 | ... O11: =N11 -> 0.45
C12: 原価 | D12: 卸売 | E12: 0.8 | F12: =E12 -> 0.8 | G12: =F12 -> 0.8 | H12: =G12 -> 0.8 | I12: =H12 -> 0.8 | J12: =I12 -> 0.8 | K12: =J12 -> 0.8 | L12: =K12 -> 0.8 | M12: =L12 -> 0.8 | ... O12: =N12 -> 0.8
C13: 原価 | D13: 企業内手売 | E13: 0.45 | F13: =E13 -> 0.45 | G13: =F13 -> 0.45 | H13: =G13 -> 0.45 | I13: =H13 -> 0.45 | J13: =I13 -> 0.45 | K13: =J13 -> 0.45 | L13: =K13 -> 0.45 | M13: =L13 -> 0.45 | ... O13: =N13 -> 0.45
C14: 変動費計
C15: 変動費計 | D15: アプリ | E15: =E24+E33+E42+E51+E60+E69+E78+E87+E96+E105 -> 0.46944792 | F15: =F24+F33+F42+F51+F60+F69+F78+F87+F96+F105 -> 0.46944792 | G15: =G24+G33+G42+G51+G60+G69+G78+G87+G96+G105 -> 0.46944792 | H15: =H24+H33+H42+H51+H60+H69+H78+H87+H96+H105 -> 0.46944792 | I15: =I24+I33+I42+I51+I60+I69+I78+I87+I96+I105 -> 0.46944792 | J15: =J24+J33+J42+J51+J60+J69+J78+J87+J96+J105 -> 0.46944792 | K15: =K24+K33+K42+K51+K60+K69+K78+K87+K96+K105 -> 0.46944792 | L15: =L24+L33+L42+L51+L60+L69+L78+L87+L96+L105 -> 0.46944792 | ... O15: =O24+O33+O42+O51+O60+O69+O78+O87+O96+O105 -> 0.46944792
C16: 変動費計 | D16: スタンド（宅急便） | E16: =E25+E34+E43+E52+E61+E70+E79+E88+E97+E106 -> 0.144 | F16: =F25+F34+F43+F52+F61+F70+F79+F88+F97+F106 -> 0.144 | G16: =G25+G34+G43+G52+G61+G70+G79+G88+G97+G106 -> 0.144 | H16: =H25+H34+H43+H52+H61+H70+H79+H88+H97+H106 -> 0.144 | I16: =I25+I34+I43+I52+I61+I70+I79+I88+I97+I106 -> 0.144 | J16: =J25+J34+J43+J52+J61+J70+J79+J88+J97+J106 -> 0.144 | K16: =K25+K34+K43+K52+K61+K70+K79+K88+K97+K106 -> 0.144 | L16: =L25+L34+L43+L52+L61+L70+L79+L88+L97+L106 -> 0.144 | ... O16: =O25+O34+O43+O52+O61+O70+O79+O88+O97+O106 -> 0.144
C17: 変動費計 | D17: スタンド（ＦＳ） | E17: =E26+E35+E44+E53+E62+E71+E80+E89+E98+E107 -> 0.0633 | F17: =F26+F35+F44+F53+F62+F71+F80+F89+F98+F107 -> 0.0633 | G17: =G26+G35+G44+G53+G62+G71+G80+G89+G98+G107 -> 0.0633 | H17: =H26+H35+H44+H53+H62+H71+H80+H89+H98+H107 -> 0.0633 | I17: =I26+I35+I44+I53+I62+I71+I80+I89+I98+I107 -> 0.0633 | J17: =J26+J35+J44+J53+J62+J71+J80+J89+J98+J107 -> 0.0633 | K17: =K26+K35+K44+K53+K62+K71+K80+K89+K98+K107 -> 0.0633 | L17: =L26+L35+L44+L53+L62+L71+L80+L89+L98+L107 -> 0.0633 | ... O17: =O26+O35+O44+O53+O62+O71+O80+O89+O98+O107 -> 0.0633
C18: 変動費計 | D18: スタンド（社外） | E18: =E27+E36+E45+E54+E63+E72+E81+E90+E99+E108 -> 0.857 | F18: =F27+F36+F45+F54+F63+F72+F81+F90+F99+F108 -> 0.857 | G18: =G27+G36+G45+G54+G63+G72+G81+G90+G99+G108 -> 0.857 | H18: =H27+H36+H45+H54+H63+H72+H81+H90+H99+H108 -> 0.857 | I18: =I27+I36+I45+I54+I63+I72+I81+I90+I99+I108 -> 0.857 | J18: =J27+J36+J45+J54+J63+J72+J81+J90+J99+J108 -> 0.857 | K18: =K27+K36+K45+K54+K63+K72+K81+K90+K99+K108 -> 0.857 | L18: =L27+L36+L45+L54+L63+L72+L81+L90+L99+L108 -> 0.857 | ... O18: =O27+O36+O45+O54+O63+O72+O81+O90+O99+O108 -> 0.857
C19: 変動費計 | D19: フロー（セミナー等） | E19: =E28+E37+E46+E55+E64+E73+E82+E91+E100+E109 -> 0.5233 | F19: =F28+F37+F46+F55+F64+F73+F82+F91+F100+F109 -> 0.5233 | G19: =G28+G37+G46+G55+G64+G73+G82+G91+G100+G109 -> 0.5233 | H19: =H28+H37+H46+H55+H64+H73+H82+H91+H100+H109 -> 0.5233 | I19: =I28+I37+I46+I55+I64+I73+I82+I91+I100+I109 -> 0.5233 | J19: =J28+J37+J46+J55+J64+J73+J82+J91+J100+J109 -> 0.5233 | K19: =K28+K37+K46+K55+K64+K73+K82+K91+K100+K109 -> 0.5233 | L19: =L28+L37+L46+L55+L64+L73+L82+L91+L100+L109 -> 0.5233 | ... O19: =O28+O37+O46+O55+O64+O73+O82+O91+O100+O109 -> 0.5233
C20: 変動費計 | D20: ＥＣストア | E20: =E29+E38+E47+E56+E65+E74+E83+E92+E101+E110 -> 0.3856 | F20: =F29+F38+F47+F56+F65+F74+F83+F92+F101+F110 -> 0.3856 | G20: =G29+G38+G47+G56+G65+G74+G83+G92+G101+G110 -> 0.3856 | H20: =H29+H38+H47+H56+H65+H74+H83+H92+H101+H110 -> 0.3856 | I20: =I29+I38+I47+I56+I65+I74+I83+I92+I101+I110 -> 0.3856 | J20: =J29+J38+J47+J56+J65+J74+J83+J92+J101+J110 -> 0.3856 | K20: =K29+K38+K47+K56+K65+K74+K83+K92+K101+K110 -> 0.3856 | L20: =L29+L38+L47+L56+L65+L74+L83+L92+L101+L110 -> 0.3856 | ... O20: =O29+O38+O47+O56+O65+O74+O83+O92+O101+O110 -> 0.3856
C21: 変動費計 | D21: 卸売 | E21: =E30+E39+E48+E57+E66+E75+E84+E93+E102+E111 -> 0.05 | F21: =F30+F39+F48+F57+F66+F75+F84+F93+F102+F111 -> 0.05 | G21: =G30+G39+G48+G57+G66+G75+G84+G93+G102+G111 -> 0.05 | H21: =H30+H39+H48+H57+H66+H75+H84+H93+H102+H111 -> 0.05 | I21: =I30+I39+I48+I57+I66+I75+I84+I93+I102+I111 -> 0.05 | J21: =J30+J39+J48+J57+J66+J75+J84+J93+J102+J111 -> 0.05 | K21: =K30+K39+K48+K57+K66+K75+K84+K93+K102+K111 -> 0.05 | L21: =L30+L39+L48+L57+L66+L75+L84+L93+L102+L111 -> 0.05 | ... O21: =O30+O39+O48+O57+O66+O75+O84+O93+O102+O111 -> 0.05
C22: 変動費計 | D22: 企業内手売 | E22: =E31+E40+E49+E58+E67+E76+E85+E94+E103+E112 -> 0.4 | F22: =F31+F40+F49+F58+F67+F76+F85+F94+F103+F112 -> 0.4 | G22: =G31+G40+G49+G58+G67+G76+G85+G94+G103+G112 -> 0.4 | H22: =H31+H40+H49+H58+H67+H76+H85+H94+H103+H112 -> 0.4 | I22: =I31+I40+I49+I58+I67+I76+I85+I94+I103+I112 -> 0.4 | J22: =J31+J40+J49+J58+J67+J76+J85+J94+J103+J112 -> 0.4 | K22: =K31+K40+K49+K58+K67+K76+K85+K94+K103+K112 -> 0.4 | L22: =L31+L40+L49+L58+L67+L76+L85+L94+L103+L112 -> 0.4 | ... O22: =O31+O40+O49+O58+O67+O76+O85+O94+O103+O112 -> 0.4
C23: 運搬費（KGL）
C24: 運搬費（KGL） | D24: アプリ | E24: 0 | F24: =E24 -> 0 | G24: =F24 -> 0 | H24: =G24 -> 0 | I24: =H24 -> 0 | J24: =I24 -> 0 | K24: =J24 -> 0 | L24: =K24 -> 0 | M24: =L24 -> 0 | ... O24: =N24 -> 0
C25: 運搬費（KGL） | D25: スタンド（宅急便） | E25: 0.012 | F25: =E25 -> 0.012 | G25: =F25 -> 0.012 | H25: =G25 -> 0.012 | I25: =H25 -> 0.012 | J25: =I25 -> 0.012 | K25: =J25 -> 0.012 | L25: =K25 -> 0.012 | M25: =L25 -> 0.012 | ... O25: =N25 -> 0.012
C26: 運搬費（KGL） | D26: スタンド（ＦＳ） | E26: 0.012 | F26: =E26 -> 0.012 | G26: =F26 -> 0.012 | H26: =G26 -> 0.012 | I26: =H26 -> 0.012 | J26: =I26 -> 0.012 | K26: =J26 -> 0.012 | L26: =K26 -> 0.012 | M26: =L26 -> 0.012 | ... O26: =N26 -> 0.012
C27: 運搬費（KGL） | D27: スタンド（社外） | E27: 0 | F27: =E27 -> 0 | G27: =F27 -> 0 | H27: =G27 -> 0 | I27: =H27 -> 0 | J27: =I27 -> 0 | K27: =J27 -> 0 | L27: =K27 -> 0 | M27: =L27 -> 0 | ... O27: =N27 -> 0
C28: 運搬費（KGL） | D28: フロー（セミナー等） | E28: 0 | F28: =E28 -> 0 | G28: =F28 -> 0 | H28: =G28 -> 0 | I28: =H28 -> 0 | J28: =I28 -> 0 | K28: =J28 -> 0 | L28: =K28 -> 0 | M28: =L28 -> 0 | ... O28: =N28 -> 0
C29: 運搬費（KGL） | D29: ＥＣストア | E29: 0.05 | F29: =E29 -> 0.05 | G29: =F29 -> 0.05 | H29: =G29 -> 0.05 | I29: =H29 -> 0.05 | J29: =I29 -> 0.05 | K29: =J29 -> 0.05 | L29: =K29 -> 0.05 | M29: =L29 -> 0.05 | ... O29: =N29 -> 0.05
C30: 運搬費（KGL） | D30: 卸売 | E30: 0.05 | F30: =E30 -> 0.05 | G30: =F30 -> 0.05 | H30: =G30 -> 0.05 | I30: =H30 -> 0.05 | J30: =I30 -> 0.05 | K30: =J30 -> 0.05 | L30: =K30 -> 0.05 | M30: =L30 -> 0.05 | ... O30: =N30 -> 0.05
C31: 運搬費（KGL） | D31: 企業内手売 | E31: 0.05 | F31: =E31 -> 0.05 | G31: =F31 -> 0.05 | H31: =G31 -> 0.05 | I31: =H31 -> 0.05 | J31: =I31 -> 0.05 | K31: =J31 -> 0.05 | L31: =K31 -> 0.05 | M31: =L31 -> 0.05 | ... O31: =N31 -> 0.05
C32: ヤマト委託費（商品）
C33: ヤマト委託費（商品） | D33: アプリ | E33: 0 | F33: =E33 -> 0 | G33: =F33 -> 0 | H33: =G33 -> 0 | I33: =H33 -> 0 | J33: =I33 -> 0 | K33: =J33 -> 0 | L33: =K33 -> 0 | M33: =L33 -> 0 | ... O33: =N33 -> 0
C34: ヤマト委託費（商品） | D34: スタンド（宅急便） | E34: 0.115 | F34: =E34 -> 0.115 | G34: =F34 -> 0.115 | H34: =G34 -> 0.115 | I34: =H34 -> 0.115 | J34: =I34 -> 0.115 | K34: =J34 -> 0.115 | L34: =K34 -> 0.115 | M34: =L34 -> 0.115 | ... O34: =N34 -> 0.115
C35: ヤマト委託費（商品） | D35: スタンド（ＦＳ） | E35: 0 | F35: =E35 -> 0 | G35: =F35 -> 0 | H35: =G35 -> 0 | I35: =H35 -> 0 | J35: =I35 -> 0 | K35: =J35 -> 0 | L35: =K35 -> 0 | M35: =L35 -> 0 | ... O35: =N35 -> 0
C36: ヤマト委託費（商品） | D36: スタンド（社外） | E36: 0 | F36: =E36 -> 0 | G36: =F36 -> 0 | H36: =G36 -> 0 | I36: =H36 -> 0 | J36: =I36 -> 0 | K36: =J36 -> 0 | L36: =K36 -> 0 | M36: =L36 -> 0 | ... O36: =N36 -> 0
C37: ヤマト委託費（商品） | D37: フロー（セミナー等） | E37: 0 | F37: =E37 -> 0 | G37: =F37 -> 0 | H37: =G37 -> 0 | I37: =H37 -> 0 | J37: =I37 -> 0 | K37: =J37 -> 0 | L37: =K37 -> 0 | M37: =L37 -> 0 | ... O37: =N37 -> 0
C38: ヤマト委託費（商品） | D38: ＥＣストア | E38: 0.333 | F38: =E38 -> 0.333 | G38: =F38 -> 0.333 | H38: =G38 -> 0.333 | I38: =H38 -> 0.333 | J38: =I38 -> 0.333 | K38: =J38 -> 0.333 | L38: =K38 -> 0.333 | M38: =L38 -> 0.333 | ... O38: =N38 -> 0.333
C39: ヤマト委託費（商品） | D39: 卸売 | E39: 0 | F39: =E39 -> 0 | G39: =F39 -> 0 | H39: =G39 -> 0 | I39: =H39 -> 0 | J39: =I39 -> 0 | K39: =J39 -> 0 | L39: =K39 -> 0 | M39: =L39 -> 0 | ... O39: =N39 -> 0
C40: ヤマト委託費（商品） | D40: 企業内手売 | E40: 0.333 | F40: =E40 -> 0.333 | G40: =F40 -> 0.333 | H40: =G40 -> 0.333 | I40: =H40 -> 0.333 | J40: =I40 -> 0.333 | K40: =J40 -> 0.333 | L40: =K40 -> 0.333 | M40: =L40 -> 0.333 | ... O40: =N40 -> 0.333
C41: NP手数料
...

Sheet 固定費
A1: 単位：千円
E3: 24年 | F3: 25年 | G3: 26年 | H3: 27年 | I3: 28年 | J3: 29年 | K3: 30年 | L3: 31年 | M3: 32年 | N3: 33年 | O3: 34年 | Q3: 単価
B4: 固定費
C5: 合計 | E5: =E15+E24+E33+E42+E51+E60+E69+E78+E87+E96+E105+E114+E123+E132+E141+E150+E159+E168+E177+E186+E195+E204+E213+E222 -> 29706.33 | F5: =F15+F24+F33+F42+F51+F60+F69+F78+F87+F96+F105+F114+F123+F132+F141+F150+F159+F168+F177+F186+F195+F204+F213+F222 -> 146632.61 | G5: =G15+G24+G33+G42+G51+G60+G69+G78+G87+G96+G105+G114+G123+G132+G141+G150+G159+G168+G177+G186+G195+G204+G213+G222 -> 201652.68 | H5: =H15+H24+H33+H42+H51+H60+H69+H78+H87+H96+H105+H114+H123+H132+H141+H150+H159+H168+H177+H186+H195+H204+H213+H222 -> 233796.94 | I5: =I15+I24+I33+I42+I51+I60+I69+I78+I87+I96+I105+I114+I123+I132+I141+I150+I159+I168+I177+I186+I195+I204+I213+I222 -> 262370.77 | J5: =J15+J24+J33+J42+J51+J60+J69+J78+J87+J96+J105+J114+J123+J132+J141+J150+J159+J168+J177+J186+J195+J204+J213+J222 -> 290061.15 | K5: =K15+K24+K33+K42+K51+K60+K69+K78+K87+K96+K105+K114+K123+K132+K141+K150+K159+K168+K177+K186+K195+K204+K213+K222 -> 316929.93 | L5: =L15+L24+L33+L42+L51+L60+L69+L78+L87+L96+L105+L114+L123+L132+L141+L150+L159+L168+L177+L186+L195+L204+L213+L222 -> 343034.62 | ... O5: =O15+O24+O33+O42+O51+O60+O69+O78+O87+O96+O105+O114+O123+O132+O141+O150+O159+O168+O177+O186+O195+O204+O213+O222 -> 417280.54
C6: 販売機器費 | D6: アプリ | E6: =E16+E25+E34+E43+E52+E61+E70+E79+E88+E97+E106+E115+E124+E133+E142+E151+E160+E169+E178+E187+E196+E205+E214+E223 -> 7538 | F6: =F16+F25+F34+F43+F52+F61+F70+F79+F88+F97+F106+F115+F124+F133+F142+F151+F160+F169+F178+F187+F196+F205+F214+F223 -> 67754.248 | G6: =G16+G25+G34+G43+G52+G61+G70+G79+G88+G97+G106+G115+G124+G133+G142+G151+G160+G169+G178+G187+G196+G205+G214+G223 -> 109417.67 | H6: =H16+H25+H34+H43+H52+H61+H70+H79+H88+H97+H106+H115+H124+H133+H142+H151+H160+H169+H178+H187+H196+H205+H214+H223 -> 123529.05 | I6: =I16+I25+I34+I43+I52+I61+I70+I79+I88+I97+I106+I115+I124+I133+I142+I151+I160+I169+I178+I187+I196+I205+I214+I223 -> 138958.79 | J6: =J16+J25+J34+J43+J52+J61+J70+J79+J88+J97+J106+J115+J124+J133+J142+J151+J160+J169+J178+J187+J196+J205+J214+J223 -> 152009.71 | K6: =K16+K25+K34+K43+K52+K61+K70+K79+K88+K97+K106+K115+K124+K133+K142+K151+K160+K169+K178+K187+K196+K205+K214+K223 -> 163666.35 | L6: =L16+L25+L34+L43+L52+L61+L70+L79+L88+L97+L106+L115+L124+L133+L142+L151+L160+L169+L178+L187+L196+L205+L214+L223 -> 174274 | ... O6: =O16+O25+O34+O43+O52+O61+O70+O79+O88+O97+O106+O115+O124+O133+O142+O151+O160+O169+O178+O187+O196+O205+O214+O223 -> 201241.72
C7: 販売機器費 | D7: スタンド（宅急便） | E7: =E17+E26+E35+E44+E53+E62+E71+E80+E89+E98+E107+E116+E125+E134+E143+E152+E161+E170+E179+E188+E197+E206+E215+E224 -> 7621 | F7: =F17+F26+F35+F44+F53+F62+F71+F80+F89+F98+F107+F116+F125+F134+F143+F152+F161+F170+F179+F188+F197+F206+F215+F224 -> 11911.511 | G7: =G17+G26+G35+G44+G53+G62+G71+G80+G89+G98+G107+G116+G125+G134+G143+G152+G161+G170+G179+G188+G197+G206+G215+G224 -> 7402.1227 | H7: =H17+H26+H35+H44+H53+H62+H71+H80+H89+H98+H107+H116+H125+H134+H143+H152+H161+H170+H179+H188+H197+H206+H215+H224 -> 3800.0637 | I7: =I17+I26+I35+I44+I53+I62+I71+I80+I89+I98+I107+I116+I125+I134+I143+I152+I161+I170+I179+I188+I197+I206+I215+I224 -> 2895.4218 | J7: =J17+J26+J35+J44+J53+J62+J71+J80+J89+J98+J107+J116+J125+J134+J143+J152+J161+J170+J179+J188+J197+J206+J215+J224 -> 2473.4422 | K7: =K17+K26+K35+K44+K53+K62+K71+K80+K89+K98+K107+K116+K125+K134+K143+K152+K161+K170+K179+K188+K197+K206+K215+K224 -> 2232.5199 | L7: =L17+L26+L35+L44+L53+L62+L71+L80+L89+L98+L107+L116+L125+L134+L143+L152+L161+L170+L179+L188+L197+L206+L215+L224 -> 2078.7944 | ... O7: =O17+O26+O35+O44+O53+O62+O71+O80+O89+O98+O107+O116+O125+O134+O143+O152+O161+O170+O179+O188+O197+O206+O215+O224 -> 1841.7801
C8: 販売機器費 | D8: スタンド（ＦＳ） | E8: =E18+E27+E36+E45+E54+E63+E72+E81+E90+E99+E108+E117+E126+E135+E144+E153+E162+E171+E180+E189+E198+E207+E216+E225 -> 703.5 | F8: =F18+F27+F36+F45+F54+F63+F72+F81+F90+F99+F108+F117+F126+F135+F144+F153+F162+F171+F180+F189+F198+F207+F216+F225 -> 22608.878 | G8: =G18+G27+G36+G45+G54+G63+G72+G81+G90+G99+G108+G117+G126+G135+G144+G153+G162+G171+G180+G189+G198+G207+G216+G225 -> 37678.948 | H8: =H18+H27+H36+H45+H54+H63+H72+H81+H90+H99+H108+H117+H126+H135+H144+H153+H162+H171+H180+H189+H198+H207+H216+H225 -> 50387.347 | I8: =I18+I27+I36+I45+I54+I63+I72+I81+I90+I99+I108+I117+I126+I135+I144+I153+I162+I171+I180+I189+I198+I207+I216+I225 -> 50460.984 | J8: =J18+J27+J36+J45+J54+J63+J72+J81+J90+J99+J108+J117+J126+J135+J144+J153+J162+J171+J180+J189+J198+J207+J216+J225 -> 50355.397 | K8: =K18+K27+K36+K45+K54+K63+K72+K81+K90+K99+K108+K117+K126+K135+K144+K153+K162+K171+K180+K189+K198+K207+K216+K225 -> 50190.864 | L8: =L18+L27+L36+L45+L54+L63+L72+L81+L90+L99+L108+L117+L126+L135+L144+L153+L162+L171+L180+L189+L198+L207+L216+L225 -> 50004.388 | ... O8: =O18+O27+O36+O45+O54+O63+O72+O81+O90+O99+O108+O117+O126+O135+O144+O153+O162+O171+O180+O189+O198+O207+O216+O225 -> 49427.132
C9: 販売機器費 | D9: スタンド（社外） | E9: =E19+E28+E37+E46+E55+E64+E73+E82+E91+E100+E109+E118+E127+E136+E145+E154+E163+E172+E181+E190+E199+E208+E217+E226 -> 398.8296 | F9: =F19+F28+F37+F46+F55+F64+F73+F82+F91+F100+F109+F118+F127+F136+F145+F154+F163+F172+F181+F190+F199+F208+F217+F226 -> 8867.3626 | G9: =G19+G28+G37+G46+G55+G64+G73+G82+G91+G100+G109+G118+G127+G136+G145+G154+G163+G172+G181+G190+G199+G208+G217+G226 -> 21330.95 | H9: =H19+H28+H37+H46+H55+H64+H73+H82+H91+H100+H109+H118+H127+H136+H145+H154+H163+H172+H181+H190+H199+H208+H217+H226 -> 35640.853 | I9: =I19+I28+I37+I46+I55+I64+I73+I82+I91+I100+I109+I118+I127+I136+I145+I154+I163+I172+I181+I190+I199+I208+I217+I226 -> 51945.365 | J9: =J19+J28+J37+J46+J55+J64+J73+J82+J91+J100+J109+J118+J127+J136+J145+J154+J163+J172+J181+J190+J199+J208+J217+J226 -> 68216.579 | K9: =K19+K28+K37+K46+K55+K64+K73+K82+K91+K100+K109+K118+K127+K136+K145+K154+K163+K172+K181+K190+K199+K208+K217+K226 -> 84477.683 | L9: =L19+L28+L37+L46+L55+L64+L73+L82+L91+L100+L109+L118+L127+L136+L145+L154+L163+L172+L181+L190+L199+L208+L217+L226 -> 100735.78 | ... O9: =O19+O28+O37+O46+O55+O64+O73+O82+O91+O100+O109+O118+O127+O136+O145+O154+O163+O172+O181+O190+O199+O208+O217+O226 -> 149513.54
C10: 販売機器費 | D10: フロー（セミナー等） | E10: =E20+E29+E38+E47+E56+E65+E74+E83+E92+E101+E110+E119+E128+E137+E146+E155+E164+E173+E182+E191+E200+E209+E218+E227 -> 12245 | F10: =F20+F29+F38+F47+F56+F65+F74+F83+F92+F101+F110+F119+F128+F137+F146+F155+F164+F173+F182+F191+F200+F209+F218+F227 -> 19940.563 | G10: =G20+G29+G38+G47+G56+G65+G74+G83+G92+G101+G110+G119+G128+G137+G146+G155+G164+G173+G182+G191+G200+G209+G218+G227 -> 16565.841 | H10: =H20+H29+H38+H47+H56+H65+H74+H83+H92+H101+H110+H119+H128+H137+H146+H155+H164+H173+H182+H191+H200+H209+H218+H227 -> 14686.648 | I10: =I20+I29+I38+I47+I56+I65+I74+I83+I92+I101+I110+I119+I128+I137+I146+I155+I164+I173+I182+I191+I200+I209+I218+I227 -> 13873.505 | J10: =J20+J29+J38+J47+J56+J65+J74+J83+J92+J101+J110+J119+J128+J137+J146+J155+J164+J173+J182+J191+J200+J209+J218+J227 -> 13488.066 | K10: =K20+K29+K38+K47+K56+K65+K74+K83+K92+K101+K110+K119+K128+K137+K146+K155+K164+K173+K182+K191+K200+K209+K218+K227 -> 13263.431 | L10: =L20+L29+L38+L47+L56+L65+L74+L83+L92+L101+L110+L119+L128+L137+L146+L155+L164+L173+L182+L191+L200+L209+L218+L227 -> 13116.521 | ... O10: =O20+O29+O38+O47+O56+O65+O74+O83+O92+O101+O110+O119+O128+O137+O146+O155+O164+O173+O182+O191+O200+O209+O218+O227 -> 12877.301
C11: 販売機器費 | D11: ＥＣストア | E11: =E21+E30+E39+E48+E57+E66+E75+E84+E93+E102+E111+E120+E129+E138+E147+E156+E165+E174+E183+E192+E201+E210+E219+E228 -> 1200 | F11: =F21+F30+F39+F48+F57+F66+F75+F84+F93+F102+F111+F120+F129+F138+F147+F156+F165+F174+F183+F192+F201+F210+F219+F228 -> 1359.8126 | G11: =G21+G30+G39+G48+G57+G66+G75+G84+G93+G102+G111+G120+G129+G138+G147+G156+G165+G174+G183+G192+G201+G210+G219+G228 -> 1289.7302 | H11: =H21+H30+H39+H48+H57+H66+H75+H84+H93+H102+H111+H120+H129+H138+H147+H156+H165+H174+H183+H192+H201+H210+H219+H228 -> 1250.7053 | I11: =I21+I30+I39+I48+I57+I66+I75+I84+I93+I102+I111+I120+I129+I138+I147+I156+I165+I174+I183+I192+I201+I210+I219+I228 -> 1233.8189 | J11: =J21+J30+J39+J48+J57+J66+J75+J84+J93+J102+J111+J120+J129+J138+J147+J156+J165+J174+J183+J192+J201+J210+J219+J228 -> 1225.8146 | K11: =K21+K30+K39+K48+K57+K66+K75+K84+K93+K102+K111+K120+K129+K138+K147+K156+K165+K174+K183+K192+K201+K210+K219+K228 -> 1221.1496 | L11: =L21+L30+L39+L48+L57+L66+L75+L84+L93+L102+L111+L120+L129+L138+L147+L156+L165+L174+L183+L192+L201+L210+L219+L228 -> 1218.0987 | ... O11: =O21+O30+O39+O48+O57+O66+O75+O84+O93+O102+O111+O120+O129+O138+O147+O156+O165+O174+O183+O192+O201+O210+O219+O228 -> 1213.1309
C12: 販売機器費 | D12: 卸売 | E12: =E22+E31+E40+E49+E58+E67+E76+E85+E94+E103+E112+E121+E130+E139+E148+E157+E166+E175+E184+E193+E202+E211+E220+E229 -> 0 | F12: =F22+F31+F40+F49+F58+F67+F76+F85+F94+F103+F112+F121+F130+F139+F148+F157+F166+F175+F184+F193+F202+F211+F220+F229 -> 8459.3204 | G12: =G22+G31+G40+G49+G58+G67+G76+G85+G94+G103+G112+G121+G130+G139+G148+G157+G166+G175+G184+G193+G202+G211+G220+G229 -> 4749.6696 | H12: =H22+H31+H40+H49+H58+H67+H76+H85+H94+H103+H112+H121+H130+H139+H148+H157+H166+H175+H184+H193+H202+H211+H220+H229 -> 2683.9724 | I12: =I22+I31+I40+I49+I58+I67+I76+I85+I94+I103+I112+I121+I130+I139+I148+I157+I166+I175+I184+I193+I202+I211+I220+I229 -> 1790.1288 | J12: =J22+J31+J40+J49+J58+J67+J76+J85+J94+J103+J112+J121+J130+J139+J148+J157+J166+J175+J184+J193+J202+J211+J220+J229 -> 1366.4358 | K12: =K22+K31+K40+K49+K58+K67+K76+K85+K94+K103+K112+K121+K130+K139+K148+K157+K166+K175+K184+K193+K202+K211+K220+K229 -> 1119.5063 | L12: =L22+L31+L40+L49+L58+L67+L76+L85+L94+L103+L112+L121+L130+L139+L148+L157+L166+L175+L184+L193+L202+L211+L220+L229 -> 958.01664 | ... O12: =O22+O31+O40+O49+O58+O67+O76+O85+O94+O103+O112+O121+O130+O139+O148+O157+O166+O175+O184+O193+O202+O211+O220+O229 -> 695.05429
C13: 販売機器費 | D13: 企業内手売 | E13: =E23+E32+E41+E50+E59+E68+E77+E86+E95+E104+E113+E122+E131+E140+E149+E158+E167+E176+E185+E194+E203+E212+E221+E230 -> 0 | F13: =F23+F32+F41+F50+F59+F68+F77+F86+F95+F104+F113+F122+F131+F140+F149+F158+F167+F176+F185+F194+F203+F212+F221+F230 -> 5730.909 | G13: =G23+G32+G41+G50+G59+G68+G77+G86+G95+G104+G113+G122+G131+G140+G149+G158+G167+G176+G185+G194+G203+G212+G221+G230 -> 3217.7436 | H13: =H23+H32+H41+H50+H59+H68+H77+H86+H95+H104+H113+H122+H131+H140+H149+H158+H167+H176+H185+H194+H203+H212+H221+H230 -> 1818.3023 | I13: =I23+I32+I41+I50+I59+I68+I77+I86+I95+I104+I113+I122+I131+I140+I149+I158+I167+I176+I185+I194+I203+I212+I221+I230 -> 1212.7529 | J13: =J23+J32+J41+J50+J59+J68+J77+J86+J95+J104+J113+J122+J131+J140+J149+J158+J167+J176+J185+J194+J203+J212+J221+J230 -> 925.71492 | K13: =K23+K32+K41+K50+K59+K68+K77+K86+K95+K104+K113+K122+K131+K140+K149+K158+K167+K176+K185+K194+K203+K212+K221+K230 -> 758.4284 | L13: =L23+L32+L41+L50+L59+L68+L77+L86+L95+L104+L113+L122+L131+L140+L149+L158+L167+L176+L185+L194+L203+L212+L221+L230 -> 649.0245 | ... O13: =O23+O32+O41+O50+O59+O68+O77+O86+O95+O104+O113+O122+O131+O140+O149+O158+O167+O176+O185+O194+O203+O212+O221+O230 -> 470.87623
B14: 固定費
C15: 販売機器費 | E15: =SUM(E16:E23) -> 4929 | F15: =SUM(F16:F23) -> 14973 | G15: =SUM(G16:G23) -> 24180 | H15: =SUM(H16:H23) -> 34410 | I15: =SUM(I16:I23) -> 34410 | J15: =SUM(J16:J23) -> 34410 | K15: =SUM(K16:K23) -> 34410 | L15: =SUM(L16:L23) -> 34410 | ... O15: =SUM(O16:O23) -> 34410
C16: 販売機器費 | D16: アプリ
C17: 販売機器費 | D17: スタンド（宅急便） | E17: =$Q$17*契約数!E35 -> 4278 | F17: =$Q$17*契約数!F35 -> 0 | G17: =$Q$17*契約数!G35 -> 0 | H17: =$Q$17*契約数!H35 -> 0 | I17: =$Q$17*契約数!I35 -> 0 | J17: =$Q$17*契約数!J35 -> 0 | K17: =$Q$17*契約数!K35 -> 0 | L17: =$Q$17*契約数!L35 -> 0 | ... O17: =$Q$17*契約数!O35 -> 0 | Q17: 93 | R17: 千円
C18: 販売機器費 | D18: スタンド（ＦＳ） | E18: =$Q$18*契約数!E36 -> 651 | F18: =$Q$18*契約数!F31 -> 14973 | G18: =$Q$18*契約数!G31 -> 24180 | H18: =$Q$18*契約数!H31 -> 34410 | I18: =$Q$18*契約数!I31 -> 34410 | J18: =$Q$18*契約数!J31 -> 34410 | K18: =$Q$18*契約数!K31 -> 34410 | L18: =$Q$18*契約数!L31 -> 34410 | M18: =$Q$18*契約数!M31 -> 34410 | ... O18: =$Q$18*契約数!O31 -> 34410 | Q18: 93 | R18: 千円
C19: 販売機器費 | D19: スタンド（社外）
C20: 販売機器費 | D20: フロー（セミナー等）
C21: 販売機器費 | D21: ＥＣストア
C22: 販売機器費 | D22: 卸売
C23: 販売機器費 | D23: 企業内手売
C24: ヤマト委託費（機器） | E24: =SUM(E25:E32) -> 212 | F24: =SUM(F25:F32) -> 644 | G24: =SUM(G25:G32) -> 1040 | H24: =SUM(H25:H32) -> 1480 | I24: =SUM(I25:I32) -> 1480 | J24: =SUM(J25:J32) -> 1480 | K24: =SUM(K25:K32) -> 1480 | L24: =SUM(L25:L32) -> 1480 | ... O24: =SUM(O25:O32) -> 1480
C25: ヤマト委託費（機器） | D25: アプリ
C26: ヤマト委託費（機器） | D26: スタンド（宅急便） | E26: =$Q$26*契約数!E35 -> 184 | F26: =$Q$26*契約数!F35 -> 0 | G26: =$Q$26*契約数!G35 -> 0 | H26: =$Q$26*契約数!H35 -> 0 | I26: =$Q$26*契約数!I35 -> 0 | J26: =$Q$26*契約数!J35 -> 0 | K26: =$Q$26*契約数!K35 -> 0 | L26: =$Q$26*契約数!L35 -> 0 | ... O26: =$Q$26*契約数!O35 -> 0 | Q26: 4 | R26: 千円
C27: ヤマト委託費（機器） | D27: スタンド（ＦＳ） | E27: =$Q$26*契約数!E36 -> 28 | F27: =$Q$26*契約数!F31 -> 644 | G27: =$Q$26*契約数!G31 -> 1040 | H27: =$Q$26*契約数!H31 -> 1480 | I27: =$Q$26*契約数!I31 -> 1480 | J27: =$Q$26*契約数!J31 -> 1480 | K27: =$Q$26*契約数!K31 -> 1480 | L27: =$Q$26*契約数!L31 -> 1480 | M27: =$Q$26*契約数!M31 -> 1480 | ... O27: =$Q$26*契約数!O31 -> 1480 | Q27: 4 | R27: 千円
C28: ヤマト委託費（機器） | D28: スタンド（社外）
C29: ヤマト委託費（機器） | D29: フロー（セミナー等）
C30: ヤマト委託費（機器） | D30: ＥＣストア
C31: ヤマト委託費（機器） | D31: 卸売
C32: ヤマト委託費（機器） | D32: 企業内手売
C33: POPスタンド・貯金箱購入費 | E33: =SUM(E34:E41) -> 79.5 | F33: =SUM(F34:F41) -> 241.5 | G33: =SUM(G34:G41) -> 390 | H33: =SUM(H34:H41) -> 555 | I33: =SUM(I34:I41) -> 555 | J33: =SUM(J34:J41) -> 555 | K33: =SUM(K34:K41) -> 555 | L33: =SUM(L34:L41) -> 555 | ... O33: =SUM(O34:O41) -> 555
C34: POPスタンド・貯金箱購入費 | D34: アプリ
C35: POPスタンド・貯金箱購入費 | D35: スタンド（宅急便） | E35: =$Q$35*契約数!E35 -> 69 | F35: =$Q$35*契約数!F35 -> 0 | G35: =$Q$35*契約数!G35 -> 0 | H35: =$Q$35*契約数!H35 -> 0 | I35: =$Q$35*契約数!I35 -> 0 | J35: =$Q$35*契約数!J35 -> 0 | K35: =$Q$35*契約数!K35 -> 0 | L35: =$Q$35*契約数!L35 -> 0 | ... O35: =$Q$35*契約数!O35 -> 0 | Q35: 1.5 | R35: 千円
C36: POPスタンド・貯金箱購入費 | D36: スタンド（ＦＳ） | E36: =$Q$36*契約数!E36 -> 10.5 | F36: =$Q$36*契約数!F31 -> 241.5 | G36: =$Q$36*契約数!G31 -> 390 | H36: =$Q$36*契約数!H31 -> 555 | I36: =$Q$36*契約数!I31 -> 555 | J36: =$Q$36*契約数!J31 -> 555 | K36: =$Q$36*契約数!K31 -> 555 | L36: =$Q$36*契約数!L31 -> 555 | M36: =$Q$36*契約数!M31 -> 555 | ... O36: =$Q$36*契約数!O31 -> 555 | Q36: 1.5 | R36: 千円
C37: POPスタンド・貯金箱購入費 | D37: スタンド（社外）
C38: POPスタンド・貯金箱購入費 | D38: フロー（セミナー等）
C39: POPスタンド・貯金箱購入費 | D39: ＥＣストア
C40: POPスタンド・貯金箱購入費 | D40: 卸売
C41: POPスタンド・貯金箱購入費 | D41: 企業内手売
...

Sheet 営業・一般管理費
A1: 単位：千円
E3: 24年 | F3: 25年 | G3: 26年 | H3: 27年 | I3: 28年 | J3: 29年 | K3: 30年 | L3: 31年 | M3: 32年 | N3: 33年 | O3: 34年 | Q3: 単価
B4: 営業・一般管理費
